INFO:root:faces: 1 at 2016-12-07 04:35:43.625851
INFO:root:faces: 0 at 2016-12-07 04:35:44.590441
INFO:root:faces: 1 at 2016-12-07 04:35:44.874212
INFO:root:faces: 2 at 2016-12-07 04:35:44.956435
INFO:root:faces: 1 at 2016-12-07 04:35:45.181039
INFO:root:faces: 0 at 2016-12-07 04:35:47.431130
INFO:root:faces: 1 at 2016-12-07 04:35:47.524381
INFO:root:faces: 0 at 2016-12-07 04:35:47.606605
INFO:root:faces: 1 at 2016-12-07 04:35:47.702863
INFO:root:faces: 0 at 2016-12-07 04:35:47.787091
INFO:root:faces: 1 at 2016-12-07 04:35:48.427888
INFO:root:faces: 0 at 2016-12-07 04:35:48.522143
INFO:root:faces: 1 at 2016-12-07 04:35:49.295231
INFO:root:faces: 2 at 2016-12-07 04:35:50.340729
INFO:root:faces: 1 at 2016-12-07 04:35:50.438983
INFO:root:faces: 0 at 2016-12-07 04:35:53.249256
INFO:root:faces: 1 at 2016-12-07 04:35:53.403668
INFO:root:faces: 0 at 2016-12-07 04:35:53.573643
INFO:root:faces: 1 at 2016-12-07 04:35:53.654859
INFO:root:faces: 0 at 2016-12-07 04:35:53.732064
INFO:root:faces: 1 at 2016-12-07 04:35:53.889025
INFO:root:faces: 0 at 2016-12-07 04:35:53.964736
INFO:root:faces: 1 at 2016-12-07 04:35:54.126171
INFO:root:faces: 0 at 2016-12-07 04:35:54.370053
INFO:root:faces: 1 at 2016-12-07 04:35:55.232339
INFO:root:faces: 0 at 2016-12-07 04:35:55.386817
INFO:root:faces: 1 at 2016-12-07 04:35:55.471042
INFO:root:faces: 2 at 2016-12-07 04:36:01.729089
INFO:root:faces: 1 at 2016-12-07 04:36:02.080043
INFO:root:faces: 2 at 2016-12-07 04:36:02.555715
INFO:root:faces: 1 at 2016-12-07 04:36:02.651100
INFO:root:faces: 1 at 2016-12-07 04:59:51.190874
INFO:root:faces: 0 at 2016-12-07 04:59:51.690252
INFO:root:faces: 1 at 2016-12-07 04:59:51.970020
INFO:root:faces: 0 at 2016-12-07 04:59:52.053246
INFO:root:faces: 1 at 2016-12-07 04:59:52.328992
INFO:root:faces: 0 at 2016-12-07 04:59:52.423246
INFO:root:faces: 1 at 2016-12-07 04:59:52.515998
INFO:root:faces: 0 at 2016-12-07 04:59:53.112620
INFO:root:faces: 1 at 2016-12-07 04:59:53.336717
INFO:root:faces: 0 at 2016-12-07 04:59:53.937493
INFO:root:faces: 1 at 2016-12-07 04:59:54.026740
INFO:root:faces: 0 at 2016-12-07 04:59:54.394842
INFO:root:faces: 1 at 2016-12-07 04:59:54.488102
INFO:root:faces: 0 at 2016-12-07 04:59:54.577579
INFO:root:faces: 1 at 2016-12-07 04:59:54.738016
INFO:root:faces: 0 at 2016-12-07 04:59:55.482203
INFO:root:faces: 1 at 2016-12-07 04:59:55.643641
INFO:root:faces: 0 at 2016-12-07 04:59:55.738897
INFO:root:faces: 1 at 2016-12-07 04:59:55.933422
INFO:root:faces: 0 at 2016-12-07 04:59:56.111907
INFO:root:faces: 1 at 2016-12-07 04:59:56.283366
INFO:root:faces: 0 at 2016-12-07 04:59:56.365590
INFO:root:faces: 1 at 2016-12-07 04:59:56.536050
INFO:root:faces: 0 at 2016-12-07 04:59:56.801771
INFO:root:faces: 1 at 2016-12-07 04:59:56.890678
INFO:root:faces: 0 at 2016-12-07 04:59:57.060153
INFO:root:faces: 1 at 2016-12-07 04:59:57.222580
INFO:root:faces: 0 at 2016-12-07 04:59:57.946782
INFO:root:faces: 1 at 2016-12-07 04:59:58.046048
INFO:root:faces: 0 at 2016-12-07 04:59:58.218514
INFO:root:faces: 1 at 2016-12-07 04:59:58.486906
INFO:root:faces: 0 at 2016-12-07 04:59:59.401361
INFO:root:faces: 1 at 2016-12-07 04:59:59.502637
INFO:root:faces: 0 at 2016-12-07 05:00:00.160200
INFO:root:faces: 1 at 2016-12-07 05:00:01.013009
INFO:root:faces: 2 at 2016-12-07 05:00:01.744890
INFO:root:faces: 1 at 2016-12-07 05:00:01.837137
INFO:root:faces: 0 at 2016-12-07 05:00:03.342764
INFO:root:faces: 1 at 2016-12-07 05:00:03.433974
INFO:root:faces: 2 at 2016-12-07 05:00:03.690177
INFO:root:faces: 1 at 2016-12-07 05:00:03.784433
INFO:root:faces: 0 at 2016-12-07 05:00:04.869870
INFO:root:faces: 2 at 2016-12-07 05:00:05.039326
INFO:root:faces: 1 at 2016-12-07 05:00:05.131590
INFO:root:faces: 0 at 2016-12-07 05:00:05.595860
INFO:root:faces: 1 at 2016-12-07 05:00:05.751780
INFO:root:faces: 0 at 2016-12-07 05:00:05.919731
INFO:root:faces: 1 at 2016-12-07 05:00:23.903089
INFO:root:faces: 0 at 2016-12-07 05:00:31.605070
INFO:root:faces: 1 at 2016-12-07 05:00:31.803639
INFO:root:faces: 2 at 2016-12-07 05:16:30.205140
INFO:root:faces: 3 at 2016-12-07 05:16:30.314437
INFO:root:faces: 2 at 2016-12-07 05:16:30.381618
INFO:root:faces: 3 at 2016-12-07 05:16:30.462838
INFO:root:faces: 2 at 2016-12-07 05:16:30.695472
INFO:root:faces: 1 at 2016-12-07 05:16:31.002314
INFO:root:faces: 2 at 2016-12-07 05:16:32.833955
INFO:root:faces: 1 at 2016-12-07 05:16:33.460291
INFO:root:faces: 2 at 2016-12-07 05:16:33.947610
INFO:root:faces: 1 at 2016-12-07 05:16:34.114563
INFO:root:faces: 2 at 2016-12-07 05:16:34.193279
INFO:root:faces: 1 at 2016-12-07 05:16:35.375293
INFO:root:faces: 2 at 2016-12-07 05:16:35.925952
INFO:root:faces: 1 at 2016-12-07 05:16:36.429563
INFO:root:faces: 0 at 2016-12-07 05:16:42.925629
INFO:root:faces: 1 at 2016-12-07 05:16:42.992807
INFO:root:faces: 0 at 2016-12-07 05:16:43.295212
INFO:root:faces: 1 at 2016-12-07 05:16:43.485730
INFO:root:faces: 0 at 2016-12-07 05:16:45.129373
INFO:root:faces: 1 at 2016-12-07 05:16:45.237669
INFO:root:faces: 2 at 2016-12-07 05:16:45.658915
INFO:root:faces: 1 at 2016-12-07 05:16:45.870493
INFO:root:faces: 2 at 2016-12-07 05:16:46.206897
INFO:root:faces: 3 at 2016-12-07 05:16:46.652975
INFO:root:faces: 2 at 2016-12-07 05:16:46.742716
INFO:root:faces: 3 at 2016-12-07 05:16:49.635182
INFO:root:faces: 2 at 2016-12-07 05:16:49.826702
INFO:root:faces: 3 at 2016-12-07 05:16:50.349120
INFO:root:faces: 2 at 2016-12-07 05:16:50.451397
INFO:root:faces: 3 at 2016-12-07 05:16:50.657957
INFO:root:faces: 2 at 2016-12-07 05:16:50.759242
INFO:root:faces: 1 at 2016-12-07 05:16:52.054071
INFO:root:faces: 2 at 2016-12-07 05:16:52.940152
INFO:root:faces: 3 at 2016-12-07 05:16:53.080036
INFO:root:faces: 1 at 2016-12-07 05:16:53.207377
INFO:root:faces: 0 at 2016-12-07 05:16:53.326713
INFO:root:faces: 1 at 2016-12-07 05:16:53.437937
INFO:root:faces: 0 at 2016-12-07 05:16:54.800034
INFO:root:faces: 1 at 2016-12-07 05:16:55.730546
INFO:root:faces: 0 at 2016-12-07 05:16:55.925574
INFO:root:faces: 1 at 2016-12-07 17:05:28.022981
INFO:root:faces: 2 at 2016-12-07 17:05:30.169972
INFO:root:faces: 1 at 2016-12-07 17:05:30.582643
INFO:root:faces: 1 at 2016-12-07 17:06:12.315796
INFO:root:faces: 0 at 2016-12-07 17:06:13.923057
INFO:root:faces: 1 at 2016-12-07 17:06:14.577188
INFO:root:faces: 1 at 2016-12-07 20:19:52.735885
INFO:root:faces: 0 at 2016-12-07 20:19:52.854215
INFO:root:faces: 1 at 2016-12-07 20:19:52.992591
INFO:root:faces: 0 at 2016-12-07 20:19:53.259820
INFO:root:faces: 1 at 2016-12-07 20:19:53.783755
INFO:root:faces: 0 at 2016-12-07 20:19:53.933161
INFO:root:faces: 1 at 2016-12-07 20:19:54.176759
INFO:root:faces: 0 at 2016-12-07 20:19:54.336192
INFO:root:faces: 1 at 2016-12-07 20:19:54.457597
INFO:root:faces: 0 at 2016-12-07 20:19:54.602755
INFO:root:faces: 1 at 2016-12-07 20:19:55.399849
INFO:root:faces: 0 at 2016-12-07 20:19:55.533208
INFO:root:faces: 1 at 2016-12-07 20:19:56.232667
INFO:root:faces: 0 at 2016-12-07 20:19:56.461841
INFO:root:faces: 1 at 2016-12-07 20:19:57.903906
INFO:root:faces: 0 at 2016-12-07 20:20:03.111382
INFO:root:faces: 1 at 2016-12-07 20:20:04.725225
INFO:root:faces: 0 at 2016-12-07 20:20:06.589463
INFO:root:faces: 1 at 2016-12-07 20:20:07.141154
INFO:root:faces: 0 at 2016-12-07 20:20:07.253560
INFO:root:faces: 1 at 2016-12-07 20:20:07.546979
INFO:root:faces: 2 at 2016-12-07 20:20:07.701521
INFO:root:faces: 0 at 2016-12-07 20:20:07.935689
INFO:root:faces: 1 at 2016-12-07 20:20:08.589781
INFO:root:faces: 0 at 2016-12-07 20:20:15.096174
INFO:root:faces: 1 at 2016-12-07 20:20:16.215724
INFO:root:faces: 1 at 2016-12-07 20:22:14.374920
INFO:root:faces: 2 at 2016-12-07 20:22:14.640274
INFO:root:faces: 1 at 2016-12-07 20:22:14.769620
INFO:root:faces: 2 at 2016-12-07 20:22:15.046362
INFO:root:faces: 1 at 2016-12-07 20:22:15.171705
INFO:root:faces: 2 at 2016-12-07 20:22:15.318783
INFO:root:faces: 1 at 2016-12-07 20:22:15.444120
INFO:root:faces: 0 at 2016-12-07 20:22:15.581052
INFO:root:faces: 1 at 2016-12-07 20:22:15.848974
INFO:root:faces: 2 at 2016-12-07 20:22:15.976347
INFO:root:faces: 1 at 2016-12-07 20:22:16.112216
INFO:root:faces: 2 at 2016-12-07 20:22:16.251124
INFO:root:faces: 1 at 2016-12-07 20:22:16.521961
INFO:root:faces: 0 at 2016-12-07 20:22:18.192676
INFO:root:faces: 1 at 2016-12-07 20:22:19.180890
INFO:root:faces: 0 at 2016-12-07 20:22:20.208271
INFO:root:faces: 1 at 2016-12-07 20:22:20.909055
INFO:root:faces: 2 at 2016-12-07 20:22:23.073169
INFO:root:faces: 1 at 2016-12-07 20:22:23.336042
INFO:root:faces: 2 at 2016-12-07 20:22:23.465939
INFO:root:faces: 1 at 2016-12-07 20:22:23.601317
INFO:root:faces: 1 at 2016-12-07 20:23:42.993632
INFO:root:faces: 2 at 2016-12-07 20:23:43.935152
INFO:root:faces: 1 at 2016-12-07 20:23:44.060489
INFO:root:faces: 0 at 2016-12-07 20:23:44.997038
INFO:root:faces: 1 at 2016-12-07 20:23:46.695589
INFO:root:faces: 0 at 2016-12-07 20:23:51.261226
INFO:root:faces: 1 at 2016-12-07 20:23:51.786237
INFO:root:faces: 0 at 2016-12-07 20:23:53.057455
INFO:root:faces: 1 at 2016-12-07 20:23:53.456171
INFO:root:faces: 0 at 2016-12-07 20:23:53.522349
INFO:root:faces: 2 at 2016-12-07 20:23:53.589529
INFO:root:faces: 1 at 2016-12-07 20:23:53.650695
INFO:root:faces: 2 at 2016-12-07 20:23:54.056788
INFO:root:faces: 3 at 2016-12-07 20:23:54.132493
INFO:root:faces: 2 at 2016-12-07 20:23:54.263346
INFO:root:faces: 1 at 2016-12-07 20:23:54.329024
INFO:root:faces: 2 at 2016-12-07 20:23:54.666438
INFO:root:faces: 3 at 2016-12-07 20:23:55.006380
INFO:root:faces: 2 at 2016-12-07 20:23:55.071557
INFO:root:faces: 1 at 2016-12-07 20:23:55.409465
INFO:root:faces: 2 at 2016-12-07 20:23:55.474642
INFO:root:faces: 1 at 2016-12-07 20:23:55.539820
INFO:root:faces: 2 at 2016-12-07 20:23:55.672176
INFO:root:faces: 1 at 2016-12-07 20:23:55.739358
INFO:root:faces: 2 at 2016-12-07 20:23:55.805534
INFO:root:faces: 1 at 2016-12-07 20:23:55.869709
INFO:root:faces: 2 at 2016-12-07 20:23:56.216647
INFO:root:faces: 1 at 2016-12-07 20:23:56.287840
INFO:root:faces: 2 at 2016-12-07 20:23:56.592664
INFO:root:faces: 1 at 2016-12-07 20:26:30.933012
INFO:root:faces: 2 at 2016-12-07 20:26:32.470592
INFO:root:faces: 1 at 2016-12-07 20:27:05.637146
INFO:root:faces: 2 at 2016-12-07 20:27:07.227241
INFO:root:faces: 1 at 2016-12-07 20:27:07.383673
INFO:root:faces: 2 at 2016-12-07 20:27:08.298623
INFO:root:faces: 1 at 2016-12-07 20:27:08.571580
INFO:root:faces: 0 at 2016-12-07 20:27:09.174042
INFO:root:faces: 1 at 2016-12-07 20:27:11.488329
INFO:root:faces: 2 at 2016-12-07 20:27:11.653705
INFO:root:faces: 1 at 2016-12-07 20:27:12.179136
INFO:root:faces: 0 at 2016-12-07 20:27:12.558359
INFO:root:faces: 2 at 2016-12-07 20:27:13.766345
INFO:root:faces: 1 at 2016-12-07 20:27:13.918818
INFO:root:faces: 2 at 2016-12-07 20:27:14.713657
INFO:root:faces: 1 at 2016-12-07 20:27:14.842002
WARNING:googleapiclient.discovery_cache:file_cache is unavailable when using oauth2client >= 4.0.0
Traceback (most recent call last):
  File "C:\Program Files (x86)\Python\Python-3.5.2\lib\site-packages\googleapiclient\discovery_cache\__init__.py", line 36, in autodetect
    from google.appengine.api import memcache
ImportError: No module named 'google'

During handling of the above exception, another exception occurred:

Traceback (most recent call last):
  File "C:\Program Files (x86)\Python\Python-3.5.2\lib\site-packages\googleapiclient\discovery_cache\file_cache.py", line 33, in <module>
    from oauth2client.contrib.locked_file import LockedFile
ImportError: No module named 'oauth2client.contrib.locked_file'

During handling of the above exception, another exception occurred:

Traceback (most recent call last):
  File "C:\Program Files (x86)\Python\Python-3.5.2\lib\site-packages\googleapiclient\discovery_cache\file_cache.py", line 37, in <module>
    from oauth2client.locked_file import LockedFile
ImportError: No module named 'oauth2client.locked_file'

During handling of the above exception, another exception occurred:

Traceback (most recent call last):
  File "C:\Program Files (x86)\Python\Python-3.5.2\lib\site-packages\googleapiclient\discovery_cache\__init__.py", line 41, in autodetect
    from . import file_cache
  File "C:\Program Files (x86)\Python\Python-3.5.2\lib\site-packages\googleapiclient\discovery_cache\file_cache.py", line 41, in <module>
    'file_cache is unavailable when using oauth2client >= 4.0.0')
ImportError: file_cache is unavailable when using oauth2client >= 4.0.0
INFO:googleapiclient.discovery:URL being requested: GET https://www.googleapis.com/discovery/v1/apis/calendar/v3/rest
INFO:googleapiclient.discovery:URL being requested: GET https://www.googleapis.com/calendar/v3/calendars/g0tostl4q2q8dc3kblkqtuuv6g%40group.calendar.google.com/events?timeMin=2016-12-08T09%3A35%3A26.114026Z&orderBy=startTime&singleEvents=true&alt=json&maxResults=5
INFO:googleapiclient.discovery:URL being requested: GET https://www.googleapis.com/calendar/v3/calendars/4dg6pu1jnusdpnkump4frglocs%40group.calendar.google.com/events?timeMin=2016-12-08T09%3A35%3A26.114026Z&orderBy=startTime&singleEvents=true&alt=json&maxResults=5
INFO:googleapiclient.discovery:URL being requested: GET https://www.googleapis.com/calendar/v3/calendars/8jaema1ucgrt3g03fjuv8r5smk%40group.calendar.google.com/events?timeMin=2016-12-08T09%3A35%3A26.114026Z&orderBy=startTime&singleEvents=true&alt=json&maxResults=5
INFO:googleapiclient.discovery:URL being requested: GET https://www.googleapis.com/calendar/v3/calendars/euokutpi37i11v0h3igns7fjh4%40group.calendar.google.com/events?timeMin=2016-12-08T09%3A35%3A26.114026Z&orderBy=startTime&singleEvents=true&alt=json&maxResults=5
INFO:googleapiclient.discovery:URL being requested: GET https://www.googleapis.com/calendar/v3/calendars/kappa.aphio%40gmail.com/events?timeMin=2016-12-08T09%3A35%3A26.114026Z&orderBy=startTime&singleEvents=true&alt=json&maxResults=5
WARNING:googleapiclient.discovery_cache:file_cache is unavailable when using oauth2client >= 4.0.0
Traceback (most recent call last):
  File "C:\Program Files (x86)\Python\Python-3.5.2\lib\site-packages\googleapiclient\discovery_cache\__init__.py", line 36, in autodetect
    from google.appengine.api import memcache
ImportError: No module named 'google'

During handling of the above exception, another exception occurred:

Traceback (most recent call last):
  File "C:\Program Files (x86)\Python\Python-3.5.2\lib\site-packages\googleapiclient\discovery_cache\file_cache.py", line 33, in <module>
    from oauth2client.contrib.locked_file import LockedFile
ImportError: No module named 'oauth2client.contrib.locked_file'

During handling of the above exception, another exception occurred:

Traceback (most recent call last):
  File "C:\Program Files (x86)\Python\Python-3.5.2\lib\site-packages\googleapiclient\discovery_cache\file_cache.py", line 37, in <module>
    from oauth2client.locked_file import LockedFile
ImportError: No module named 'oauth2client.locked_file'

During handling of the above exception, another exception occurred:

Traceback (most recent call last):
  File "C:\Program Files (x86)\Python\Python-3.5.2\lib\site-packages\googleapiclient\discovery_cache\__init__.py", line 41, in autodetect
    from . import file_cache
  File "C:\Program Files (x86)\Python\Python-3.5.2\lib\site-packages\googleapiclient\discovery_cache\file_cache.py", line 41, in <module>
    'file_cache is unavailable when using oauth2client >= 4.0.0')
ImportError: file_cache is unavailable when using oauth2client >= 4.0.0
INFO:googleapiclient.discovery:URL being requested: GET https://www.googleapis.com/discovery/v1/apis/calendar/v3/rest
INFO:googleapiclient.discovery:URL being requested: GET https://www.googleapis.com/calendar/v3/calendars/g0tostl4q2q8dc3kblkqtuuv6g%40group.calendar.google.com/events?timeMin=2016-12-08T09%3A36%3A34.452466Z&orderBy=startTime&singleEvents=true&alt=json&maxResults=5
INFO:googleapiclient.discovery:URL being requested: GET https://www.googleapis.com/calendar/v3/calendars/4dg6pu1jnusdpnkump4frglocs%40group.calendar.google.com/events?timeMin=2016-12-08T09%3A36%3A34.452466Z&orderBy=startTime&singleEvents=true&alt=json&maxResults=5
INFO:googleapiclient.discovery:URL being requested: GET https://www.googleapis.com/calendar/v3/calendars/8jaema1ucgrt3g03fjuv8r5smk%40group.calendar.google.com/events?timeMin=2016-12-08T09%3A36%3A34.452466Z&orderBy=startTime&singleEvents=true&alt=json&maxResults=5
INFO:googleapiclient.discovery:URL being requested: GET https://www.googleapis.com/calendar/v3/calendars/euokutpi37i11v0h3igns7fjh4%40group.calendar.google.com/events?timeMin=2016-12-08T09%3A36%3A34.452466Z&orderBy=startTime&singleEvents=true&alt=json&maxResults=5
INFO:googleapiclient.discovery:URL being requested: GET https://www.googleapis.com/calendar/v3/calendars/kappa.aphio%40gmail.com/events?timeMin=2016-12-08T09%3A36%3A34.452466Z&orderBy=startTime&singleEvents=true&alt=json&maxResults=5
WARNING:googleapiclient.discovery_cache:file_cache is unavailable when using oauth2client >= 4.0.0
Traceback (most recent call last):
  File "C:\Program Files (x86)\Python\Python-3.5.2\lib\site-packages\googleapiclient\discovery_cache\__init__.py", line 36, in autodetect
    from google.appengine.api import memcache
ImportError: No module named 'google'

During handling of the above exception, another exception occurred:

Traceback (most recent call last):
  File "C:\Program Files (x86)\Python\Python-3.5.2\lib\site-packages\googleapiclient\discovery_cache\file_cache.py", line 33, in <module>
    from oauth2client.contrib.locked_file import LockedFile
ImportError: No module named 'oauth2client.contrib.locked_file'

During handling of the above exception, another exception occurred:

Traceback (most recent call last):
  File "C:\Program Files (x86)\Python\Python-3.5.2\lib\site-packages\googleapiclient\discovery_cache\file_cache.py", line 37, in <module>
    from oauth2client.locked_file import LockedFile
ImportError: No module named 'oauth2client.locked_file'

During handling of the above exception, another exception occurred:

Traceback (most recent call last):
  File "C:\Program Files (x86)\Python\Python-3.5.2\lib\site-packages\googleapiclient\discovery_cache\__init__.py", line 41, in autodetect
    from . import file_cache
  File "C:\Program Files (x86)\Python\Python-3.5.2\lib\site-packages\googleapiclient\discovery_cache\file_cache.py", line 41, in <module>
    'file_cache is unavailable when using oauth2client >= 4.0.0')
ImportError: file_cache is unavailable when using oauth2client >= 4.0.0
INFO:googleapiclient.discovery:URL being requested: GET https://www.googleapis.com/discovery/v1/apis/calendar/v3/rest
INFO:googleapiclient.discovery:URL being requested: GET https://www.googleapis.com/calendar/v3/calendars/g0tostl4q2q8dc3kblkqtuuv6g%40group.calendar.google.com/events?singleEvents=true&alt=json&orderBy=startTime&timeMin=2016-12-08T09%3A39%3A49.783377Z&maxResults=5
INFO:googleapiclient.discovery:URL being requested: GET https://www.googleapis.com/calendar/v3/calendars/4dg6pu1jnusdpnkump4frglocs%40group.calendar.google.com/events?singleEvents=true&alt=json&orderBy=startTime&timeMin=2016-12-08T09%3A39%3A49.783377Z&maxResults=5
INFO:googleapiclient.discovery:URL being requested: GET https://www.googleapis.com/calendar/v3/calendars/8jaema1ucgrt3g03fjuv8r5smk%40group.calendar.google.com/events?singleEvents=true&alt=json&orderBy=startTime&timeMin=2016-12-08T09%3A39%3A49.783377Z&maxResults=5
INFO:googleapiclient.discovery:URL being requested: GET https://www.googleapis.com/calendar/v3/calendars/euokutpi37i11v0h3igns7fjh4%40group.calendar.google.com/events?singleEvents=true&alt=json&orderBy=startTime&timeMin=2016-12-08T09%3A39%3A49.783377Z&maxResults=5
INFO:googleapiclient.discovery:URL being requested: GET https://www.googleapis.com/calendar/v3/calendars/kappa.aphio%40gmail.com/events?singleEvents=true&alt=json&orderBy=startTime&timeMin=2016-12-08T09%3A39%3A49.783377Z&maxResults=5
WARNING:googleapiclient.discovery_cache:file_cache is unavailable when using oauth2client >= 4.0.0
Traceback (most recent call last):
  File "C:\Program Files (x86)\Python\Python-3.5.2\lib\site-packages\googleapiclient\discovery_cache\__init__.py", line 36, in autodetect
    from google.appengine.api import memcache
ImportError: No module named 'google'

During handling of the above exception, another exception occurred:

Traceback (most recent call last):
  File "C:\Program Files (x86)\Python\Python-3.5.2\lib\site-packages\googleapiclient\discovery_cache\file_cache.py", line 33, in <module>
    from oauth2client.contrib.locked_file import LockedFile
ImportError: No module named 'oauth2client.contrib.locked_file'

During handling of the above exception, another exception occurred:

Traceback (most recent call last):
  File "C:\Program Files (x86)\Python\Python-3.5.2\lib\site-packages\googleapiclient\discovery_cache\file_cache.py", line 37, in <module>
    from oauth2client.locked_file import LockedFile
ImportError: No module named 'oauth2client.locked_file'

During handling of the above exception, another exception occurred:

Traceback (most recent call last):
  File "C:\Program Files (x86)\Python\Python-3.5.2\lib\site-packages\googleapiclient\discovery_cache\__init__.py", line 41, in autodetect
    from . import file_cache
  File "C:\Program Files (x86)\Python\Python-3.5.2\lib\site-packages\googleapiclient\discovery_cache\file_cache.py", line 41, in <module>
    'file_cache is unavailable when using oauth2client >= 4.0.0')
ImportError: file_cache is unavailable when using oauth2client >= 4.0.0
INFO:googleapiclient.discovery:URL being requested: GET https://www.googleapis.com/discovery/v1/apis/calendar/v3/rest
INFO:googleapiclient.discovery:URL being requested: GET https://www.googleapis.com/calendar/v3/calendars/g0tostl4q2q8dc3kblkqtuuv6g%40group.calendar.google.com/events?singleEvents=true&alt=json&maxResults=5&timeMin=2016-12-08T09%3A42%3A36.565454Z&orderBy=startTime
INFO:googleapiclient.discovery:URL being requested: GET https://www.googleapis.com/calendar/v3/calendars/4dg6pu1jnusdpnkump4frglocs%40group.calendar.google.com/events?singleEvents=true&alt=json&maxResults=5&timeMin=2016-12-08T09%3A42%3A36.565454Z&orderBy=startTime
INFO:googleapiclient.discovery:URL being requested: GET https://www.googleapis.com/calendar/v3/calendars/8jaema1ucgrt3g03fjuv8r5smk%40group.calendar.google.com/events?singleEvents=true&alt=json&maxResults=5&timeMin=2016-12-08T09%3A42%3A36.565454Z&orderBy=startTime
INFO:googleapiclient.discovery:URL being requested: GET https://www.googleapis.com/calendar/v3/calendars/euokutpi37i11v0h3igns7fjh4%40group.calendar.google.com/events?singleEvents=true&alt=json&maxResults=5&timeMin=2016-12-08T09%3A42%3A36.565454Z&orderBy=startTime
INFO:googleapiclient.discovery:URL being requested: GET https://www.googleapis.com/calendar/v3/calendars/kappa.aphio%40gmail.com/events?singleEvents=true&alt=json&maxResults=5&timeMin=2016-12-08T09%3A42%3A36.565454Z&orderBy=startTime
WARNING:googleapiclient.discovery_cache:file_cache is unavailable when using oauth2client >= 4.0.0
Traceback (most recent call last):
  File "C:\Program Files (x86)\Python\Python-3.5.2\lib\site-packages\googleapiclient\discovery_cache\__init__.py", line 36, in autodetect
    from google.appengine.api import memcache
ImportError: No module named 'google'

During handling of the above exception, another exception occurred:

Traceback (most recent call last):
  File "C:\Program Files (x86)\Python\Python-3.5.2\lib\site-packages\googleapiclient\discovery_cache\file_cache.py", line 33, in <module>
    from oauth2client.contrib.locked_file import LockedFile
ImportError: No module named 'oauth2client.contrib.locked_file'

During handling of the above exception, another exception occurred:

Traceback (most recent call last):
  File "C:\Program Files (x86)\Python\Python-3.5.2\lib\site-packages\googleapiclient\discovery_cache\file_cache.py", line 37, in <module>
    from oauth2client.locked_file import LockedFile
ImportError: No module named 'oauth2client.locked_file'

During handling of the above exception, another exception occurred:

Traceback (most recent call last):
  File "C:\Program Files (x86)\Python\Python-3.5.2\lib\site-packages\googleapiclient\discovery_cache\__init__.py", line 41, in autodetect
    from . import file_cache
  File "C:\Program Files (x86)\Python\Python-3.5.2\lib\site-packages\googleapiclient\discovery_cache\file_cache.py", line 41, in <module>
    'file_cache is unavailable when using oauth2client >= 4.0.0')
ImportError: file_cache is unavailable when using oauth2client >= 4.0.0
INFO:googleapiclient.discovery:URL being requested: GET https://www.googleapis.com/discovery/v1/apis/calendar/v3/rest
INFO:googleapiclient.discovery:URL being requested: GET https://www.googleapis.com/calendar/v3/calendars/g0tostl4q2q8dc3kblkqtuuv6g%40group.calendar.google.com/events?maxResults=5&singleEvents=true&alt=json&orderBy=startTime&timeMin=2016-12-08T10%3A06%3A43.336886Z
INFO:googleapiclient.discovery:URL being requested: GET https://www.googleapis.com/calendar/v3/calendars/4dg6pu1jnusdpnkump4frglocs%40group.calendar.google.com/events?maxResults=5&singleEvents=true&alt=json&orderBy=startTime&timeMin=2016-12-08T10%3A06%3A43.336886Z
INFO:googleapiclient.discovery:URL being requested: GET https://www.googleapis.com/calendar/v3/calendars/8jaema1ucgrt3g03fjuv8r5smk%40group.calendar.google.com/events?maxResults=5&singleEvents=true&alt=json&orderBy=startTime&timeMin=2016-12-08T10%3A06%3A43.336886Z
INFO:googleapiclient.discovery:URL being requested: GET https://www.googleapis.com/calendar/v3/calendars/euokutpi37i11v0h3igns7fjh4%40group.calendar.google.com/events?maxResults=5&singleEvents=true&alt=json&orderBy=startTime&timeMin=2016-12-08T10%3A06%3A43.336886Z
INFO:googleapiclient.discovery:URL being requested: GET https://www.googleapis.com/calendar/v3/calendars/kappa.aphio%40gmail.com/events?maxResults=5&singleEvents=true&alt=json&orderBy=startTime&timeMin=2016-12-08T10%3A06%3A43.336886Z
WARNING:googleapiclient.discovery_cache:file_cache is unavailable when using oauth2client >= 4.0.0
Traceback (most recent call last):
  File "C:\Program Files (x86)\Python\Python-3.5.2\lib\site-packages\googleapiclient\discovery_cache\__init__.py", line 36, in autodetect
    from google.appengine.api import memcache
ImportError: No module named 'google'

During handling of the above exception, another exception occurred:

Traceback (most recent call last):
  File "C:\Program Files (x86)\Python\Python-3.5.2\lib\site-packages\googleapiclient\discovery_cache\file_cache.py", line 33, in <module>
    from oauth2client.contrib.locked_file import LockedFile
ImportError: No module named 'oauth2client.contrib.locked_file'

During handling of the above exception, another exception occurred:

Traceback (most recent call last):
  File "C:\Program Files (x86)\Python\Python-3.5.2\lib\site-packages\googleapiclient\discovery_cache\file_cache.py", line 37, in <module>
    from oauth2client.locked_file import LockedFile
ImportError: No module named 'oauth2client.locked_file'

During handling of the above exception, another exception occurred:

Traceback (most recent call last):
  File "C:\Program Files (x86)\Python\Python-3.5.2\lib\site-packages\googleapiclient\discovery_cache\__init__.py", line 41, in autodetect
    from . import file_cache
  File "C:\Program Files (x86)\Python\Python-3.5.2\lib\site-packages\googleapiclient\discovery_cache\file_cache.py", line 41, in <module>
    'file_cache is unavailable when using oauth2client >= 4.0.0')
ImportError: file_cache is unavailable when using oauth2client >= 4.0.0
INFO:googleapiclient.discovery:URL being requested: GET https://www.googleapis.com/discovery/v1/apis/calendar/v3/rest
INFO:googleapiclient.discovery:URL being requested: GET https://www.googleapis.com/calendar/v3/calendars/g0tostl4q2q8dc3kblkqtuuv6g%40group.calendar.google.com/events?orderBy=startTime&alt=json&timeMin=2016-12-08T10%3A13%3A47.107714Z&maxResults=5&singleEvents=true
INFO:googleapiclient.discovery:URL being requested: GET https://www.googleapis.com/calendar/v3/calendars/4dg6pu1jnusdpnkump4frglocs%40group.calendar.google.com/events?orderBy=startTime&alt=json&timeMin=2016-12-08T10%3A13%3A47.107714Z&maxResults=5&singleEvents=true
INFO:googleapiclient.discovery:URL being requested: GET https://www.googleapis.com/calendar/v3/calendars/8jaema1ucgrt3g03fjuv8r5smk%40group.calendar.google.com/events?orderBy=startTime&alt=json&timeMin=2016-12-08T10%3A13%3A47.107714Z&maxResults=5&singleEvents=true
INFO:googleapiclient.discovery:URL being requested: GET https://www.googleapis.com/calendar/v3/calendars/euokutpi37i11v0h3igns7fjh4%40group.calendar.google.com/events?orderBy=startTime&alt=json&timeMin=2016-12-08T10%3A13%3A47.107714Z&maxResults=5&singleEvents=true
INFO:googleapiclient.discovery:URL being requested: GET https://www.googleapis.com/calendar/v3/calendars/kappa.aphio%40gmail.com/events?orderBy=startTime&alt=json&timeMin=2016-12-08T10%3A13%3A47.107714Z&maxResults=5&singleEvents=true
WARNING:googleapiclient.discovery_cache:file_cache is unavailable when using oauth2client >= 4.0.0
Traceback (most recent call last):
  File "C:\Program Files (x86)\Python\Python-3.5.2\lib\site-packages\googleapiclient\discovery_cache\__init__.py", line 36, in autodetect
    from google.appengine.api import memcache
ImportError: No module named 'google'

During handling of the above exception, another exception occurred:

Traceback (most recent call last):
  File "C:\Program Files (x86)\Python\Python-3.5.2\lib\site-packages\googleapiclient\discovery_cache\file_cache.py", line 33, in <module>
    from oauth2client.contrib.locked_file import LockedFile
ImportError: No module named 'oauth2client.contrib.locked_file'

During handling of the above exception, another exception occurred:

Traceback (most recent call last):
  File "C:\Program Files (x86)\Python\Python-3.5.2\lib\site-packages\googleapiclient\discovery_cache\file_cache.py", line 37, in <module>
    from oauth2client.locked_file import LockedFile
ImportError: No module named 'oauth2client.locked_file'

During handling of the above exception, another exception occurred:

Traceback (most recent call last):
  File "C:\Program Files (x86)\Python\Python-3.5.2\lib\site-packages\googleapiclient\discovery_cache\__init__.py", line 41, in autodetect
    from . import file_cache
  File "C:\Program Files (x86)\Python\Python-3.5.2\lib\site-packages\googleapiclient\discovery_cache\file_cache.py", line 41, in <module>
    'file_cache is unavailable when using oauth2client >= 4.0.0')
ImportError: file_cache is unavailable when using oauth2client >= 4.0.0
INFO:googleapiclient.discovery:URL being requested: GET https://www.googleapis.com/discovery/v1/apis/calendar/v3/rest
INFO:googleapiclient.discovery:URL being requested: GET https://www.googleapis.com/calendar/v3/calendars/g0tostl4q2q8dc3kblkqtuuv6g%40group.calendar.google.com/events?alt=json&orderBy=startTime&maxResults=5&singleEvents=true&timeMin=2016-12-08T10%3A27%3A25.364626Z
INFO:googleapiclient.discovery:URL being requested: GET https://www.googleapis.com/calendar/v3/calendars/4dg6pu1jnusdpnkump4frglocs%40group.calendar.google.com/events?alt=json&orderBy=startTime&maxResults=5&singleEvents=true&timeMin=2016-12-08T10%3A27%3A25.364626Z
INFO:googleapiclient.discovery:URL being requested: GET https://www.googleapis.com/calendar/v3/calendars/8jaema1ucgrt3g03fjuv8r5smk%40group.calendar.google.com/events?alt=json&orderBy=startTime&maxResults=5&singleEvents=true&timeMin=2016-12-08T10%3A27%3A25.364626Z
INFO:googleapiclient.discovery:URL being requested: GET https://www.googleapis.com/calendar/v3/calendars/euokutpi37i11v0h3igns7fjh4%40group.calendar.google.com/events?alt=json&orderBy=startTime&maxResults=5&singleEvents=true&timeMin=2016-12-08T10%3A27%3A25.364626Z
INFO:googleapiclient.discovery:URL being requested: GET https://www.googleapis.com/calendar/v3/calendars/kappa.aphio%40gmail.com/events?alt=json&orderBy=startTime&maxResults=5&singleEvents=true&timeMin=2016-12-08T10%3A27%3A25.364626Z
WARNING:googleapiclient.discovery_cache:file_cache is unavailable when using oauth2client >= 4.0.0
Traceback (most recent call last):
  File "C:\Program Files (x86)\Python\Python-3.5.2\lib\site-packages\googleapiclient\discovery_cache\__init__.py", line 36, in autodetect
    from google.appengine.api import memcache
ImportError: No module named 'google'

During handling of the above exception, another exception occurred:

Traceback (most recent call last):
  File "C:\Program Files (x86)\Python\Python-3.5.2\lib\site-packages\googleapiclient\discovery_cache\file_cache.py", line 33, in <module>
    from oauth2client.contrib.locked_file import LockedFile
ImportError: No module named 'oauth2client.contrib.locked_file'

During handling of the above exception, another exception occurred:

Traceback (most recent call last):
  File "C:\Program Files (x86)\Python\Python-3.5.2\lib\site-packages\googleapiclient\discovery_cache\file_cache.py", line 37, in <module>
    from oauth2client.locked_file import LockedFile
ImportError: No module named 'oauth2client.locked_file'

During handling of the above exception, another exception occurred:

Traceback (most recent call last):
  File "C:\Program Files (x86)\Python\Python-3.5.2\lib\site-packages\googleapiclient\discovery_cache\__init__.py", line 41, in autodetect
    from . import file_cache
  File "C:\Program Files (x86)\Python\Python-3.5.2\lib\site-packages\googleapiclient\discovery_cache\file_cache.py", line 41, in <module>
    'file_cache is unavailable when using oauth2client >= 4.0.0')
ImportError: file_cache is unavailable when using oauth2client >= 4.0.0
INFO:googleapiclient.discovery:URL being requested: GET https://www.googleapis.com/discovery/v1/apis/calendar/v3/rest
INFO:googleapiclient.discovery:URL being requested: GET https://www.googleapis.com/calendar/v3/calendars/g0tostl4q2q8dc3kblkqtuuv6g%40group.calendar.google.com/events?maxResults=5&singleEvents=true&timeMin=2016-12-08T10%3A29%3A52.148484Z&alt=json&orderBy=startTime
INFO:googleapiclient.discovery:URL being requested: GET https://www.googleapis.com/calendar/v3/calendars/4dg6pu1jnusdpnkump4frglocs%40group.calendar.google.com/events?maxResults=5&singleEvents=true&timeMin=2016-12-08T10%3A29%3A52.148484Z&alt=json&orderBy=startTime
INFO:googleapiclient.discovery:URL being requested: GET https://www.googleapis.com/calendar/v3/calendars/8jaema1ucgrt3g03fjuv8r5smk%40group.calendar.google.com/events?maxResults=5&singleEvents=true&timeMin=2016-12-08T10%3A29%3A52.148484Z&alt=json&orderBy=startTime
INFO:googleapiclient.discovery:URL being requested: GET https://www.googleapis.com/calendar/v3/calendars/euokutpi37i11v0h3igns7fjh4%40group.calendar.google.com/events?maxResults=5&singleEvents=true&timeMin=2016-12-08T10%3A29%3A52.148484Z&alt=json&orderBy=startTime
WARNING:googleapiclient.discovery_cache:file_cache is unavailable when using oauth2client >= 4.0.0
Traceback (most recent call last):
  File "C:\Program Files (x86)\Python\Python-3.5.2\lib\site-packages\googleapiclient\discovery_cache\__init__.py", line 36, in autodetect
    from google.appengine.api import memcache
ImportError: No module named 'google'

During handling of the above exception, another exception occurred:

Traceback (most recent call last):
  File "C:\Program Files (x86)\Python\Python-3.5.2\lib\site-packages\googleapiclient\discovery_cache\file_cache.py", line 33, in <module>
    from oauth2client.contrib.locked_file import LockedFile
ImportError: No module named 'oauth2client.contrib.locked_file'

During handling of the above exception, another exception occurred:

Traceback (most recent call last):
  File "C:\Program Files (x86)\Python\Python-3.5.2\lib\site-packages\googleapiclient\discovery_cache\file_cache.py", line 37, in <module>
    from oauth2client.locked_file import LockedFile
ImportError: No module named 'oauth2client.locked_file'

During handling of the above exception, another exception occurred:

Traceback (most recent call last):
  File "C:\Program Files (x86)\Python\Python-3.5.2\lib\site-packages\googleapiclient\discovery_cache\__init__.py", line 41, in autodetect
    from . import file_cache
  File "C:\Program Files (x86)\Python\Python-3.5.2\lib\site-packages\googleapiclient\discovery_cache\file_cache.py", line 41, in <module>
    'file_cache is unavailable when using oauth2client >= 4.0.0')
ImportError: file_cache is unavailable when using oauth2client >= 4.0.0
INFO:googleapiclient.discovery:URL being requested: GET https://www.googleapis.com/discovery/v1/apis/calendar/v3/rest
INFO:googleapiclient.discovery:URL being requested: GET https://www.googleapis.com/calendar/v3/calendars/g0tostl4q2q8dc3kblkqtuuv6g%40group.calendar.google.com/events?maxResults=5&singleEvents=true&timeMin=2016-12-08T10%3A30%3A04.581839Z&alt=json&orderBy=startTime
INFO:googleapiclient.discovery:URL being requested: GET https://www.googleapis.com/calendar/v3/calendars/4dg6pu1jnusdpnkump4frglocs%40group.calendar.google.com/events?maxResults=5&singleEvents=true&timeMin=2016-12-08T10%3A30%3A04.581839Z&alt=json&orderBy=startTime
INFO:googleapiclient.discovery:URL being requested: GET https://www.googleapis.com/calendar/v3/calendars/8jaema1ucgrt3g03fjuv8r5smk%40group.calendar.google.com/events?maxResults=5&singleEvents=true&timeMin=2016-12-08T10%3A30%3A04.581839Z&alt=json&orderBy=startTime
INFO:googleapiclient.discovery:URL being requested: GET https://www.googleapis.com/calendar/v3/calendars/euokutpi37i11v0h3igns7fjh4%40group.calendar.google.com/events?maxResults=5&singleEvents=true&timeMin=2016-12-08T10%3A30%3A04.581839Z&alt=json&orderBy=startTime
WARNING:googleapiclient.discovery_cache:file_cache is unavailable when using oauth2client >= 4.0.0
Traceback (most recent call last):
  File "C:\Program Files (x86)\Python\Python-3.5.2\lib\site-packages\googleapiclient\discovery_cache\__init__.py", line 36, in autodetect
    from google.appengine.api import memcache
ImportError: No module named 'google'

During handling of the above exception, another exception occurred:

Traceback (most recent call last):
  File "C:\Program Files (x86)\Python\Python-3.5.2\lib\site-packages\googleapiclient\discovery_cache\file_cache.py", line 33, in <module>
    from oauth2client.contrib.locked_file import LockedFile
ImportError: No module named 'oauth2client.contrib.locked_file'

During handling of the above exception, another exception occurred:

Traceback (most recent call last):
  File "C:\Program Files (x86)\Python\Python-3.5.2\lib\site-packages\googleapiclient\discovery_cache\file_cache.py", line 37, in <module>
    from oauth2client.locked_file import LockedFile
ImportError: No module named 'oauth2client.locked_file'

During handling of the above exception, another exception occurred:

Traceback (most recent call last):
  File "C:\Program Files (x86)\Python\Python-3.5.2\lib\site-packages\googleapiclient\discovery_cache\__init__.py", line 41, in autodetect
    from . import file_cache
  File "C:\Program Files (x86)\Python\Python-3.5.2\lib\site-packages\googleapiclient\discovery_cache\file_cache.py", line 41, in <module>
    'file_cache is unavailable when using oauth2client >= 4.0.0')
ImportError: file_cache is unavailable when using oauth2client >= 4.0.0
INFO:googleapiclient.discovery:URL being requested: GET https://www.googleapis.com/discovery/v1/apis/calendar/v3/rest
INFO:googleapiclient.discovery:URL being requested: GET https://www.googleapis.com/calendar/v3/calendars/g0tostl4q2q8dc3kblkqtuuv6g%40group.calendar.google.com/events?maxResults=5&singleEvents=true&timeMin=2016-12-08T10%3A30%3A21.975555Z&alt=json&orderBy=startTime
INFO:googleapiclient.discovery:URL being requested: GET https://www.googleapis.com/calendar/v3/calendars/4dg6pu1jnusdpnkump4frglocs%40group.calendar.google.com/events?maxResults=5&singleEvents=true&timeMin=2016-12-08T10%3A30%3A21.975555Z&alt=json&orderBy=startTime
INFO:googleapiclient.discovery:URL being requested: GET https://www.googleapis.com/calendar/v3/calendars/8jaema1ucgrt3g03fjuv8r5smk%40group.calendar.google.com/events?maxResults=5&singleEvents=true&timeMin=2016-12-08T10%3A30%3A21.975555Z&alt=json&orderBy=startTime
INFO:googleapiclient.discovery:URL being requested: GET https://www.googleapis.com/calendar/v3/calendars/euokutpi37i11v0h3igns7fjh4%40group.calendar.google.com/events?maxResults=5&singleEvents=true&timeMin=2016-12-08T10%3A30%3A21.975555Z&alt=json&orderBy=startTime
WARNING:googleapiclient.discovery_cache:file_cache is unavailable when using oauth2client >= 4.0.0
Traceback (most recent call last):
  File "C:\Program Files (x86)\Python\Python-3.5.2\lib\site-packages\googleapiclient\discovery_cache\__init__.py", line 36, in autodetect
    from google.appengine.api import memcache
ImportError: No module named 'google'

During handling of the above exception, another exception occurred:

Traceback (most recent call last):
  File "C:\Program Files (x86)\Python\Python-3.5.2\lib\site-packages\googleapiclient\discovery_cache\file_cache.py", line 33, in <module>
    from oauth2client.contrib.locked_file import LockedFile
ImportError: No module named 'oauth2client.contrib.locked_file'

During handling of the above exception, another exception occurred:

Traceback (most recent call last):
  File "C:\Program Files (x86)\Python\Python-3.5.2\lib\site-packages\googleapiclient\discovery_cache\file_cache.py", line 37, in <module>
    from oauth2client.locked_file import LockedFile
ImportError: No module named 'oauth2client.locked_file'

During handling of the above exception, another exception occurred:

Traceback (most recent call last):
  File "C:\Program Files (x86)\Python\Python-3.5.2\lib\site-packages\googleapiclient\discovery_cache\__init__.py", line 41, in autodetect
    from . import file_cache
  File "C:\Program Files (x86)\Python\Python-3.5.2\lib\site-packages\googleapiclient\discovery_cache\file_cache.py", line 41, in <module>
    'file_cache is unavailable when using oauth2client >= 4.0.0')
ImportError: file_cache is unavailable when using oauth2client >= 4.0.0
INFO:googleapiclient.discovery:URL being requested: GET https://www.googleapis.com/discovery/v1/apis/calendar/v3/rest
INFO:googleapiclient.discovery:URL being requested: GET https://www.googleapis.com/calendar/v3/calendars/g0tostl4q2q8dc3kblkqtuuv6g%40group.calendar.google.com/events?maxResults=5&singleEvents=true&timeMin=2016-12-08T10%3A30%3A22.569547Z&alt=json&orderBy=startTime
INFO:googleapiclient.discovery:URL being requested: GET https://www.googleapis.com/calendar/v3/calendars/4dg6pu1jnusdpnkump4frglocs%40group.calendar.google.com/events?maxResults=5&singleEvents=true&timeMin=2016-12-08T10%3A30%3A22.569547Z&alt=json&orderBy=startTime
INFO:googleapiclient.discovery:URL being requested: GET https://www.googleapis.com/calendar/v3/calendars/8jaema1ucgrt3g03fjuv8r5smk%40group.calendar.google.com/events?maxResults=5&singleEvents=true&timeMin=2016-12-08T10%3A30%3A22.569547Z&alt=json&orderBy=startTime
INFO:googleapiclient.discovery:URL being requested: GET https://www.googleapis.com/calendar/v3/calendars/euokutpi37i11v0h3igns7fjh4%40group.calendar.google.com/events?maxResults=5&singleEvents=true&timeMin=2016-12-08T10%3A30%3A22.569547Z&alt=json&orderBy=startTime
WARNING:googleapiclient.discovery_cache:file_cache is unavailable when using oauth2client >= 4.0.0
Traceback (most recent call last):
  File "C:\Program Files (x86)\Python\Python-3.5.2\lib\site-packages\googleapiclient\discovery_cache\__init__.py", line 36, in autodetect
    from google.appengine.api import memcache
ImportError: No module named 'google'

During handling of the above exception, another exception occurred:

Traceback (most recent call last):
  File "C:\Program Files (x86)\Python\Python-3.5.2\lib\site-packages\googleapiclient\discovery_cache\file_cache.py", line 33, in <module>
    from oauth2client.contrib.locked_file import LockedFile
ImportError: No module named 'oauth2client.contrib.locked_file'

During handling of the above exception, another exception occurred:

Traceback (most recent call last):
  File "C:\Program Files (x86)\Python\Python-3.5.2\lib\site-packages\googleapiclient\discovery_cache\file_cache.py", line 37, in <module>
    from oauth2client.locked_file import LockedFile
ImportError: No module named 'oauth2client.locked_file'

During handling of the above exception, another exception occurred:

Traceback (most recent call last):
  File "C:\Program Files (x86)\Python\Python-3.5.2\lib\site-packages\googleapiclient\discovery_cache\__init__.py", line 41, in autodetect
    from . import file_cache
  File "C:\Program Files (x86)\Python\Python-3.5.2\lib\site-packages\googleapiclient\discovery_cache\file_cache.py", line 41, in <module>
    'file_cache is unavailable when using oauth2client >= 4.0.0')
ImportError: file_cache is unavailable when using oauth2client >= 4.0.0
INFO:googleapiclient.discovery:URL being requested: GET https://www.googleapis.com/discovery/v1/apis/calendar/v3/rest
INFO:googleapiclient.discovery:URL being requested: GET https://www.googleapis.com/calendar/v3/calendars/g0tostl4q2q8dc3kblkqtuuv6g%40group.calendar.google.com/events?maxResults=5&singleEvents=true&timeMin=2016-12-08T10%3A30%3A23.161869Z&alt=json&orderBy=startTime
INFO:googleapiclient.discovery:URL being requested: GET https://www.googleapis.com/calendar/v3/calendars/4dg6pu1jnusdpnkump4frglocs%40group.calendar.google.com/events?maxResults=5&singleEvents=true&timeMin=2016-12-08T10%3A30%3A23.161869Z&alt=json&orderBy=startTime
INFO:googleapiclient.discovery:URL being requested: GET https://www.googleapis.com/calendar/v3/calendars/8jaema1ucgrt3g03fjuv8r5smk%40group.calendar.google.com/events?maxResults=5&singleEvents=true&timeMin=2016-12-08T10%3A30%3A23.161869Z&alt=json&orderBy=startTime
INFO:googleapiclient.discovery:URL being requested: GET https://www.googleapis.com/calendar/v3/calendars/euokutpi37i11v0h3igns7fjh4%40group.calendar.google.com/events?maxResults=5&singleEvents=true&timeMin=2016-12-08T10%3A30%3A23.161869Z&alt=json&orderBy=startTime
WARNING:googleapiclient.discovery_cache:file_cache is unavailable when using oauth2client >= 4.0.0
Traceback (most recent call last):
  File "C:\Program Files (x86)\Python\Python-3.5.2\lib\site-packages\googleapiclient\discovery_cache\__init__.py", line 36, in autodetect
    from google.appengine.api import memcache
ImportError: No module named 'google'

During handling of the above exception, another exception occurred:

Traceback (most recent call last):
  File "C:\Program Files (x86)\Python\Python-3.5.2\lib\site-packages\googleapiclient\discovery_cache\file_cache.py", line 33, in <module>
    from oauth2client.contrib.locked_file import LockedFile
ImportError: No module named 'oauth2client.contrib.locked_file'

During handling of the above exception, another exception occurred:

Traceback (most recent call last):
  File "C:\Program Files (x86)\Python\Python-3.5.2\lib\site-packages\googleapiclient\discovery_cache\file_cache.py", line 37, in <module>
    from oauth2client.locked_file import LockedFile
ImportError: No module named 'oauth2client.locked_file'

During handling of the above exception, another exception occurred:

Traceback (most recent call last):
  File "C:\Program Files (x86)\Python\Python-3.5.2\lib\site-packages\googleapiclient\discovery_cache\__init__.py", line 41, in autodetect
    from . import file_cache
  File "C:\Program Files (x86)\Python\Python-3.5.2\lib\site-packages\googleapiclient\discovery_cache\file_cache.py", line 41, in <module>
    'file_cache is unavailable when using oauth2client >= 4.0.0')
ImportError: file_cache is unavailable when using oauth2client >= 4.0.0
INFO:googleapiclient.discovery:URL being requested: GET https://www.googleapis.com/discovery/v1/apis/calendar/v3/rest
INFO:googleapiclient.discovery:URL being requested: GET https://www.googleapis.com/calendar/v3/calendars/g0tostl4q2q8dc3kblkqtuuv6g%40group.calendar.google.com/events?maxResults=5&singleEvents=true&timeMin=2016-12-08T10%3A30%3A34.378018Z&alt=json&orderBy=startTime
INFO:oauth2client.transport:Refreshing due to a 401 (attempt 1/2)
INFO:oauth2client.client:Refreshing access_token
INFO:googleapiclient.discovery:URL being requested: GET https://www.googleapis.com/calendar/v3/calendars/4dg6pu1jnusdpnkump4frglocs%40group.calendar.google.com/events?maxResults=5&singleEvents=true&timeMin=2016-12-08T10%3A30%3A34.378018Z&alt=json&orderBy=startTime
INFO:googleapiclient.discovery:URL being requested: GET https://www.googleapis.com/calendar/v3/calendars/8jaema1ucgrt3g03fjuv8r5smk%40group.calendar.google.com/events?maxResults=5&singleEvents=true&timeMin=2016-12-08T10%3A30%3A34.378018Z&alt=json&orderBy=startTime
INFO:googleapiclient.discovery:URL being requested: GET https://www.googleapis.com/calendar/v3/calendars/euokutpi37i11v0h3igns7fjh4%40group.calendar.google.com/events?maxResults=5&singleEvents=true&timeMin=2016-12-08T10%3A30%3A34.378018Z&alt=json&orderBy=startTime
WARNING:googleapiclient.discovery_cache:file_cache is unavailable when using oauth2client >= 4.0.0
Traceback (most recent call last):
  File "C:\Program Files (x86)\Python\Python-3.5.2\lib\site-packages\googleapiclient\discovery_cache\__init__.py", line 36, in autodetect
    from google.appengine.api import memcache
ImportError: No module named 'google'

During handling of the above exception, another exception occurred:

Traceback (most recent call last):
  File "C:\Program Files (x86)\Python\Python-3.5.2\lib\site-packages\googleapiclient\discovery_cache\file_cache.py", line 33, in <module>
    from oauth2client.contrib.locked_file import LockedFile
ImportError: No module named 'oauth2client.contrib.locked_file'

During handling of the above exception, another exception occurred:

Traceback (most recent call last):
  File "C:\Program Files (x86)\Python\Python-3.5.2\lib\site-packages\googleapiclient\discovery_cache\file_cache.py", line 37, in <module>
    from oauth2client.locked_file import LockedFile
ImportError: No module named 'oauth2client.locked_file'

During handling of the above exception, another exception occurred:

Traceback (most recent call last):
  File "C:\Program Files (x86)\Python\Python-3.5.2\lib\site-packages\googleapiclient\discovery_cache\__init__.py", line 41, in autodetect
    from . import file_cache
  File "C:\Program Files (x86)\Python\Python-3.5.2\lib\site-packages\googleapiclient\discovery_cache\file_cache.py", line 41, in <module>
    'file_cache is unavailable when using oauth2client >= 4.0.0')
ImportError: file_cache is unavailable when using oauth2client >= 4.0.0
INFO:googleapiclient.discovery:URL being requested: GET https://www.googleapis.com/discovery/v1/apis/calendar/v3/rest
INFO:googleapiclient.discovery:URL being requested: GET https://www.googleapis.com/calendar/v3/calendars/g0tostl4q2q8dc3kblkqtuuv6g%40group.calendar.google.com/events?maxResults=5&singleEvents=true&timeMin=2016-12-08T10%3A30%3A35.262071Z&alt=json&orderBy=startTime
INFO:googleapiclient.discovery:URL being requested: GET https://www.googleapis.com/calendar/v3/calendars/4dg6pu1jnusdpnkump4frglocs%40group.calendar.google.com/events?maxResults=5&singleEvents=true&timeMin=2016-12-08T10%3A30%3A35.262071Z&alt=json&orderBy=startTime
INFO:googleapiclient.discovery:URL being requested: GET https://www.googleapis.com/calendar/v3/calendars/8jaema1ucgrt3g03fjuv8r5smk%40group.calendar.google.com/events?maxResults=5&singleEvents=true&timeMin=2016-12-08T10%3A30%3A35.262071Z&alt=json&orderBy=startTime
INFO:googleapiclient.discovery:URL being requested: GET https://www.googleapis.com/calendar/v3/calendars/euokutpi37i11v0h3igns7fjh4%40group.calendar.google.com/events?maxResults=5&singleEvents=true&timeMin=2016-12-08T10%3A30%3A35.262071Z&alt=json&orderBy=startTime
WARNING:googleapiclient.discovery_cache:file_cache is unavailable when using oauth2client >= 4.0.0
Traceback (most recent call last):
  File "C:\Program Files (x86)\Python\Python-3.5.2\lib\site-packages\googleapiclient\discovery_cache\__init__.py", line 36, in autodetect
    from google.appengine.api import memcache
ImportError: No module named 'google'

During handling of the above exception, another exception occurred:

Traceback (most recent call last):
  File "C:\Program Files (x86)\Python\Python-3.5.2\lib\site-packages\googleapiclient\discovery_cache\file_cache.py", line 33, in <module>
    from oauth2client.contrib.locked_file import LockedFile
ImportError: No module named 'oauth2client.contrib.locked_file'

During handling of the above exception, another exception occurred:

Traceback (most recent call last):
  File "C:\Program Files (x86)\Python\Python-3.5.2\lib\site-packages\googleapiclient\discovery_cache\file_cache.py", line 37, in <module>
    from oauth2client.locked_file import LockedFile
ImportError: No module named 'oauth2client.locked_file'

During handling of the above exception, another exception occurred:

Traceback (most recent call last):
  File "C:\Program Files (x86)\Python\Python-3.5.2\lib\site-packages\googleapiclient\discovery_cache\__init__.py", line 41, in autodetect
    from . import file_cache
  File "C:\Program Files (x86)\Python\Python-3.5.2\lib\site-packages\googleapiclient\discovery_cache\file_cache.py", line 41, in <module>
    'file_cache is unavailable when using oauth2client >= 4.0.0')
ImportError: file_cache is unavailable when using oauth2client >= 4.0.0
INFO:googleapiclient.discovery:URL being requested: GET https://www.googleapis.com/discovery/v1/apis/calendar/v3/rest
INFO:googleapiclient.discovery:URL being requested: GET https://www.googleapis.com/calendar/v3/calendars/g0tostl4q2q8dc3kblkqtuuv6g%40group.calendar.google.com/events?maxResults=5&singleEvents=true&timeMin=2016-12-08T10%3A30%3A36.240993Z&alt=json&orderBy=startTime
INFO:googleapiclient.discovery:URL being requested: GET https://www.googleapis.com/calendar/v3/calendars/4dg6pu1jnusdpnkump4frglocs%40group.calendar.google.com/events?maxResults=5&singleEvents=true&timeMin=2016-12-08T10%3A30%3A36.240993Z&alt=json&orderBy=startTime
INFO:googleapiclient.discovery:URL being requested: GET https://www.googleapis.com/calendar/v3/calendars/8jaema1ucgrt3g03fjuv8r5smk%40group.calendar.google.com/events?maxResults=5&singleEvents=true&timeMin=2016-12-08T10%3A30%3A36.240993Z&alt=json&orderBy=startTime
INFO:googleapiclient.discovery:URL being requested: GET https://www.googleapis.com/calendar/v3/calendars/euokutpi37i11v0h3igns7fjh4%40group.calendar.google.com/events?maxResults=5&singleEvents=true&timeMin=2016-12-08T10%3A30%3A36.240993Z&alt=json&orderBy=startTime
WARNING:googleapiclient.discovery_cache:file_cache is unavailable when using oauth2client >= 4.0.0
Traceback (most recent call last):
  File "C:\Program Files (x86)\Python\Python-3.5.2\lib\site-packages\googleapiclient\discovery_cache\__init__.py", line 36, in autodetect
    from google.appengine.api import memcache
ImportError: No module named 'google'

During handling of the above exception, another exception occurred:

Traceback (most recent call last):
  File "C:\Program Files (x86)\Python\Python-3.5.2\lib\site-packages\googleapiclient\discovery_cache\file_cache.py", line 33, in <module>
    from oauth2client.contrib.locked_file import LockedFile
ImportError: No module named 'oauth2client.contrib.locked_file'

During handling of the above exception, another exception occurred:

Traceback (most recent call last):
  File "C:\Program Files (x86)\Python\Python-3.5.2\lib\site-packages\googleapiclient\discovery_cache\file_cache.py", line 37, in <module>
    from oauth2client.locked_file import LockedFile
ImportError: No module named 'oauth2client.locked_file'

During handling of the above exception, another exception occurred:

Traceback (most recent call last):
  File "C:\Program Files (x86)\Python\Python-3.5.2\lib\site-packages\googleapiclient\discovery_cache\__init__.py", line 41, in autodetect
    from . import file_cache
  File "C:\Program Files (x86)\Python\Python-3.5.2\lib\site-packages\googleapiclient\discovery_cache\file_cache.py", line 41, in <module>
    'file_cache is unavailable when using oauth2client >= 4.0.0')
ImportError: file_cache is unavailable when using oauth2client >= 4.0.0
INFO:googleapiclient.discovery:URL being requested: GET https://www.googleapis.com/discovery/v1/apis/calendar/v3/rest
INFO:googleapiclient.discovery:URL being requested: GET https://www.googleapis.com/calendar/v3/calendars/g0tostl4q2q8dc3kblkqtuuv6g%40group.calendar.google.com/events?maxResults=5&singleEvents=true&timeMin=2016-12-08T10%3A30%3A36.855659Z&alt=json&orderBy=startTime
INFO:googleapiclient.discovery:URL being requested: GET https://www.googleapis.com/calendar/v3/calendars/4dg6pu1jnusdpnkump4frglocs%40group.calendar.google.com/events?maxResults=5&singleEvents=true&timeMin=2016-12-08T10%3A30%3A36.855659Z&alt=json&orderBy=startTime
INFO:googleapiclient.discovery:URL being requested: GET https://www.googleapis.com/calendar/v3/calendars/8jaema1ucgrt3g03fjuv8r5smk%40group.calendar.google.com/events?maxResults=5&singleEvents=true&timeMin=2016-12-08T10%3A30%3A36.855659Z&alt=json&orderBy=startTime
INFO:googleapiclient.discovery:URL being requested: GET https://www.googleapis.com/calendar/v3/calendars/euokutpi37i11v0h3igns7fjh4%40group.calendar.google.com/events?maxResults=5&singleEvents=true&timeMin=2016-12-08T10%3A30%3A36.855659Z&alt=json&orderBy=startTime
WARNING:googleapiclient.discovery_cache:file_cache is unavailable when using oauth2client >= 4.0.0
Traceback (most recent call last):
  File "C:\Program Files (x86)\Python\Python-3.5.2\lib\site-packages\googleapiclient\discovery_cache\__init__.py", line 36, in autodetect
    from google.appengine.api import memcache
ImportError: No module named 'google'

During handling of the above exception, another exception occurred:

Traceback (most recent call last):
  File "C:\Program Files (x86)\Python\Python-3.5.2\lib\site-packages\googleapiclient\discovery_cache\file_cache.py", line 33, in <module>
    from oauth2client.contrib.locked_file import LockedFile
ImportError: No module named 'oauth2client.contrib.locked_file'

During handling of the above exception, another exception occurred:

Traceback (most recent call last):
  File "C:\Program Files (x86)\Python\Python-3.5.2\lib\site-packages\googleapiclient\discovery_cache\file_cache.py", line 37, in <module>
    from oauth2client.locked_file import LockedFile
ImportError: No module named 'oauth2client.locked_file'

During handling of the above exception, another exception occurred:

Traceback (most recent call last):
  File "C:\Program Files (x86)\Python\Python-3.5.2\lib\site-packages\googleapiclient\discovery_cache\__init__.py", line 41, in autodetect
    from . import file_cache
  File "C:\Program Files (x86)\Python\Python-3.5.2\lib\site-packages\googleapiclient\discovery_cache\file_cache.py", line 41, in <module>
    'file_cache is unavailable when using oauth2client >= 4.0.0')
ImportError: file_cache is unavailable when using oauth2client >= 4.0.0
INFO:googleapiclient.discovery:URL being requested: GET https://www.googleapis.com/discovery/v1/apis/calendar/v3/rest
INFO:googleapiclient.discovery:URL being requested: GET https://www.googleapis.com/calendar/v3/calendars/g0tostl4q2q8dc3kblkqtuuv6g%40group.calendar.google.com/events?maxResults=5&singleEvents=true&timeMin=2016-12-08T10%3A30%3A37.510553Z&alt=json&orderBy=startTime
INFO:googleapiclient.discovery:URL being requested: GET https://www.googleapis.com/calendar/v3/calendars/4dg6pu1jnusdpnkump4frglocs%40group.calendar.google.com/events?maxResults=5&singleEvents=true&timeMin=2016-12-08T10%3A30%3A37.510553Z&alt=json&orderBy=startTime
INFO:googleapiclient.discovery:URL being requested: GET https://www.googleapis.com/calendar/v3/calendars/8jaema1ucgrt3g03fjuv8r5smk%40group.calendar.google.com/events?maxResults=5&singleEvents=true&timeMin=2016-12-08T10%3A30%3A37.510553Z&alt=json&orderBy=startTime
INFO:googleapiclient.discovery:URL being requested: GET https://www.googleapis.com/calendar/v3/calendars/euokutpi37i11v0h3igns7fjh4%40group.calendar.google.com/events?maxResults=5&singleEvents=true&timeMin=2016-12-08T10%3A30%3A37.510553Z&alt=json&orderBy=startTime
WARNING:googleapiclient.discovery_cache:file_cache is unavailable when using oauth2client >= 4.0.0
Traceback (most recent call last):
  File "C:\Program Files (x86)\Python\Python-3.5.2\lib\site-packages\googleapiclient\discovery_cache\__init__.py", line 36, in autodetect
    from google.appengine.api import memcache
ImportError: No module named 'google'

During handling of the above exception, another exception occurred:

Traceback (most recent call last):
  File "C:\Program Files (x86)\Python\Python-3.5.2\lib\site-packages\googleapiclient\discovery_cache\file_cache.py", line 33, in <module>
    from oauth2client.contrib.locked_file import LockedFile
ImportError: No module named 'oauth2client.contrib.locked_file'

During handling of the above exception, another exception occurred:

Traceback (most recent call last):
  File "C:\Program Files (x86)\Python\Python-3.5.2\lib\site-packages\googleapiclient\discovery_cache\file_cache.py", line 37, in <module>
    from oauth2client.locked_file import LockedFile
ImportError: No module named 'oauth2client.locked_file'

During handling of the above exception, another exception occurred:

Traceback (most recent call last):
  File "C:\Program Files (x86)\Python\Python-3.5.2\lib\site-packages\googleapiclient\discovery_cache\__init__.py", line 41, in autodetect
    from . import file_cache
  File "C:\Program Files (x86)\Python\Python-3.5.2\lib\site-packages\googleapiclient\discovery_cache\file_cache.py", line 41, in <module>
    'file_cache is unavailable when using oauth2client >= 4.0.0')
ImportError: file_cache is unavailable when using oauth2client >= 4.0.0
INFO:googleapiclient.discovery:URL being requested: GET https://www.googleapis.com/discovery/v1/apis/calendar/v3/rest
INFO:googleapiclient.discovery:URL being requested: GET https://www.googleapis.com/calendar/v3/calendars/g0tostl4q2q8dc3kblkqtuuv6g%40group.calendar.google.com/events?maxResults=5&singleEvents=true&timeMin=2016-12-08T10%3A30%3A38.165462Z&alt=json&orderBy=startTime
INFO:googleapiclient.discovery:URL being requested: GET https://www.googleapis.com/calendar/v3/calendars/4dg6pu1jnusdpnkump4frglocs%40group.calendar.google.com/events?maxResults=5&singleEvents=true&timeMin=2016-12-08T10%3A30%3A38.165462Z&alt=json&orderBy=startTime
INFO:googleapiclient.discovery:URL being requested: GET https://www.googleapis.com/calendar/v3/calendars/8jaema1ucgrt3g03fjuv8r5smk%40group.calendar.google.com/events?maxResults=5&singleEvents=true&timeMin=2016-12-08T10%3A30%3A38.165462Z&alt=json&orderBy=startTime
INFO:googleapiclient.discovery:URL being requested: GET https://www.googleapis.com/calendar/v3/calendars/euokutpi37i11v0h3igns7fjh4%40group.calendar.google.com/events?maxResults=5&singleEvents=true&timeMin=2016-12-08T10%3A30%3A38.165462Z&alt=json&orderBy=startTime
WARNING:googleapiclient.discovery_cache:file_cache is unavailable when using oauth2client >= 4.0.0
Traceback (most recent call last):
  File "C:\Program Files (x86)\Python\Python-3.5.2\lib\site-packages\googleapiclient\discovery_cache\__init__.py", line 36, in autodetect
    from google.appengine.api import memcache
ImportError: No module named 'google'

During handling of the above exception, another exception occurred:

Traceback (most recent call last):
  File "C:\Program Files (x86)\Python\Python-3.5.2\lib\site-packages\googleapiclient\discovery_cache\file_cache.py", line 33, in <module>
    from oauth2client.contrib.locked_file import LockedFile
ImportError: No module named 'oauth2client.contrib.locked_file'

During handling of the above exception, another exception occurred:

Traceback (most recent call last):
  File "C:\Program Files (x86)\Python\Python-3.5.2\lib\site-packages\googleapiclient\discovery_cache\file_cache.py", line 37, in <module>
    from oauth2client.locked_file import LockedFile
ImportError: No module named 'oauth2client.locked_file'

During handling of the above exception, another exception occurred:

Traceback (most recent call last):
  File "C:\Program Files (x86)\Python\Python-3.5.2\lib\site-packages\googleapiclient\discovery_cache\__init__.py", line 41, in autodetect
    from . import file_cache
  File "C:\Program Files (x86)\Python\Python-3.5.2\lib\site-packages\googleapiclient\discovery_cache\file_cache.py", line 41, in <module>
    'file_cache is unavailable when using oauth2client >= 4.0.0')
ImportError: file_cache is unavailable when using oauth2client >= 4.0.0
INFO:googleapiclient.discovery:URL being requested: GET https://www.googleapis.com/discovery/v1/apis/calendar/v3/rest
INFO:googleapiclient.discovery:URL being requested: GET https://www.googleapis.com/calendar/v3/calendars/g0tostl4q2q8dc3kblkqtuuv6g%40group.calendar.google.com/events?maxResults=5&orderBy=startTime&timeMin=2016-12-08T10%3A31%3A59.832357Z&singleEvents=true&alt=json
INFO:googleapiclient.discovery:URL being requested: GET https://www.googleapis.com/calendar/v3/calendars/4dg6pu1jnusdpnkump4frglocs%40group.calendar.google.com/events?maxResults=5&orderBy=startTime&timeMin=2016-12-08T10%3A31%3A59.832357Z&singleEvents=true&alt=json
INFO:googleapiclient.discovery:URL being requested: GET https://www.googleapis.com/calendar/v3/calendars/8jaema1ucgrt3g03fjuv8r5smk%40group.calendar.google.com/events?maxResults=5&orderBy=startTime&timeMin=2016-12-08T10%3A31%3A59.832357Z&singleEvents=true&alt=json
INFO:googleapiclient.discovery:URL being requested: GET https://www.googleapis.com/calendar/v3/calendars/euokutpi37i11v0h3igns7fjh4%40group.calendar.google.com/events?maxResults=5&orderBy=startTime&timeMin=2016-12-08T10%3A31%3A59.832357Z&singleEvents=true&alt=json
WARNING:googleapiclient.discovery_cache:file_cache is unavailable when using oauth2client >= 4.0.0
Traceback (most recent call last):
  File "C:\Program Files (x86)\Python\Python-3.5.2\lib\site-packages\googleapiclient\discovery_cache\__init__.py", line 36, in autodetect
    from google.appengine.api import memcache
ImportError: No module named 'google'

During handling of the above exception, another exception occurred:

Traceback (most recent call last):
  File "C:\Program Files (x86)\Python\Python-3.5.2\lib\site-packages\googleapiclient\discovery_cache\file_cache.py", line 33, in <module>
    from oauth2client.contrib.locked_file import LockedFile
ImportError: No module named 'oauth2client.contrib.locked_file'

During handling of the above exception, another exception occurred:

Traceback (most recent call last):
  File "C:\Program Files (x86)\Python\Python-3.5.2\lib\site-packages\googleapiclient\discovery_cache\file_cache.py", line 37, in <module>
    from oauth2client.locked_file import LockedFile
ImportError: No module named 'oauth2client.locked_file'

During handling of the above exception, another exception occurred:

Traceback (most recent call last):
  File "C:\Program Files (x86)\Python\Python-3.5.2\lib\site-packages\googleapiclient\discovery_cache\__init__.py", line 41, in autodetect
    from . import file_cache
  File "C:\Program Files (x86)\Python\Python-3.5.2\lib\site-packages\googleapiclient\discovery_cache\file_cache.py", line 41, in <module>
    'file_cache is unavailable when using oauth2client >= 4.0.0')
ImportError: file_cache is unavailable when using oauth2client >= 4.0.0
INFO:googleapiclient.discovery:URL being requested: GET https://www.googleapis.com/discovery/v1/apis/calendar/v3/rest
INFO:googleapiclient.discovery:URL being requested: GET https://www.googleapis.com/calendar/v3/calendars/g0tostl4q2q8dc3kblkqtuuv6g%40group.calendar.google.com/events?maxResults=5&orderBy=startTime&timeMin=2016-12-08T10%3A32%3A42.358482Z&singleEvents=true&alt=json
INFO:googleapiclient.discovery:URL being requested: GET https://www.googleapis.com/calendar/v3/calendars/4dg6pu1jnusdpnkump4frglocs%40group.calendar.google.com/events?maxResults=5&orderBy=startTime&timeMin=2016-12-08T10%3A32%3A42.358482Z&singleEvents=true&alt=json
INFO:googleapiclient.discovery:URL being requested: GET https://www.googleapis.com/calendar/v3/calendars/8jaema1ucgrt3g03fjuv8r5smk%40group.calendar.google.com/events?maxResults=5&orderBy=startTime&timeMin=2016-12-08T10%3A32%3A42.358482Z&singleEvents=true&alt=json
INFO:googleapiclient.discovery:URL being requested: GET https://www.googleapis.com/calendar/v3/calendars/euokutpi37i11v0h3igns7fjh4%40group.calendar.google.com/events?maxResults=5&orderBy=startTime&timeMin=2016-12-08T10%3A32%3A42.358482Z&singleEvents=true&alt=json
WARNING:googleapiclient.discovery_cache:file_cache is unavailable when using oauth2client >= 4.0.0
Traceback (most recent call last):
  File "C:\Program Files (x86)\Python\Python-3.5.2\lib\site-packages\googleapiclient\discovery_cache\__init__.py", line 36, in autodetect
    from google.appengine.api import memcache
ImportError: No module named 'google'

During handling of the above exception, another exception occurred:

Traceback (most recent call last):
  File "C:\Program Files (x86)\Python\Python-3.5.2\lib\site-packages\googleapiclient\discovery_cache\file_cache.py", line 33, in <module>
    from oauth2client.contrib.locked_file import LockedFile
ImportError: No module named 'oauth2client.contrib.locked_file'

During handling of the above exception, another exception occurred:

Traceback (most recent call last):
  File "C:\Program Files (x86)\Python\Python-3.5.2\lib\site-packages\googleapiclient\discovery_cache\file_cache.py", line 37, in <module>
    from oauth2client.locked_file import LockedFile
ImportError: No module named 'oauth2client.locked_file'

During handling of the above exception, another exception occurred:

Traceback (most recent call last):
  File "C:\Program Files (x86)\Python\Python-3.5.2\lib\site-packages\googleapiclient\discovery_cache\__init__.py", line 41, in autodetect
    from . import file_cache
  File "C:\Program Files (x86)\Python\Python-3.5.2\lib\site-packages\googleapiclient\discovery_cache\file_cache.py", line 41, in <module>
    'file_cache is unavailable when using oauth2client >= 4.0.0')
ImportError: file_cache is unavailable when using oauth2client >= 4.0.0
INFO:googleapiclient.discovery:URL being requested: GET https://www.googleapis.com/discovery/v1/apis/calendar/v3/rest
INFO:googleapiclient.discovery:URL being requested: GET https://www.googleapis.com/calendar/v3/calendars/g0tostl4q2q8dc3kblkqtuuv6g%40group.calendar.google.com/events?maxResults=5&orderBy=startTime&timeMin=2016-12-08T10%3A32%3A43.167686Z&singleEvents=true&alt=json
INFO:googleapiclient.discovery:URL being requested: GET https://www.googleapis.com/calendar/v3/calendars/4dg6pu1jnusdpnkump4frglocs%40group.calendar.google.com/events?maxResults=5&orderBy=startTime&timeMin=2016-12-08T10%3A32%3A43.167686Z&singleEvents=true&alt=json
INFO:googleapiclient.discovery:URL being requested: GET https://www.googleapis.com/calendar/v3/calendars/8jaema1ucgrt3g03fjuv8r5smk%40group.calendar.google.com/events?maxResults=5&orderBy=startTime&timeMin=2016-12-08T10%3A32%3A43.167686Z&singleEvents=true&alt=json
INFO:googleapiclient.discovery:URL being requested: GET https://www.googleapis.com/calendar/v3/calendars/euokutpi37i11v0h3igns7fjh4%40group.calendar.google.com/events?maxResults=5&orderBy=startTime&timeMin=2016-12-08T10%3A32%3A43.167686Z&singleEvents=true&alt=json
WARNING:googleapiclient.discovery_cache:file_cache is unavailable when using oauth2client >= 4.0.0
Traceback (most recent call last):
  File "C:\Program Files (x86)\Python\Python-3.5.2\lib\site-packages\googleapiclient\discovery_cache\__init__.py", line 36, in autodetect
    from google.appengine.api import memcache
ImportError: No module named 'google'

During handling of the above exception, another exception occurred:

Traceback (most recent call last):
  File "C:\Program Files (x86)\Python\Python-3.5.2\lib\site-packages\googleapiclient\discovery_cache\file_cache.py", line 33, in <module>
    from oauth2client.contrib.locked_file import LockedFile
ImportError: No module named 'oauth2client.contrib.locked_file'

During handling of the above exception, another exception occurred:

Traceback (most recent call last):
  File "C:\Program Files (x86)\Python\Python-3.5.2\lib\site-packages\googleapiclient\discovery_cache\file_cache.py", line 37, in <module>
    from oauth2client.locked_file import LockedFile
ImportError: No module named 'oauth2client.locked_file'

During handling of the above exception, another exception occurred:

Traceback (most recent call last):
  File "C:\Program Files (x86)\Python\Python-3.5.2\lib\site-packages\googleapiclient\discovery_cache\__init__.py", line 41, in autodetect
    from . import file_cache
  File "C:\Program Files (x86)\Python\Python-3.5.2\lib\site-packages\googleapiclient\discovery_cache\file_cache.py", line 41, in <module>
    'file_cache is unavailable when using oauth2client >= 4.0.0')
ImportError: file_cache is unavailable when using oauth2client >= 4.0.0
INFO:googleapiclient.discovery:URL being requested: GET https://www.googleapis.com/discovery/v1/apis/calendar/v3/rest
INFO:googleapiclient.discovery:URL being requested: GET https://www.googleapis.com/calendar/v3/calendars/g0tostl4q2q8dc3kblkqtuuv6g%40group.calendar.google.com/events?alt=json&maxResults=5&singleEvents=true&orderBy=startTime&timeMin=2016-12-08T11%3A08%3A47.819820Z
INFO:googleapiclient.discovery:URL being requested: GET https://www.googleapis.com/calendar/v3/calendars/4dg6pu1jnusdpnkump4frglocs%40group.calendar.google.com/events?alt=json&maxResults=5&singleEvents=true&orderBy=startTime&timeMin=2016-12-08T11%3A08%3A47.819820Z
INFO:googleapiclient.discovery:URL being requested: GET https://www.googleapis.com/calendar/v3/calendars/8jaema1ucgrt3g03fjuv8r5smk%40group.calendar.google.com/events?alt=json&maxResults=5&singleEvents=true&orderBy=startTime&timeMin=2016-12-08T11%3A08%3A47.819820Z
INFO:googleapiclient.discovery:URL being requested: GET https://www.googleapis.com/calendar/v3/calendars/euokutpi37i11v0h3igns7fjh4%40group.calendar.google.com/events?alt=json&maxResults=5&singleEvents=true&orderBy=startTime&timeMin=2016-12-08T11%3A08%3A47.819820Z
WARNING:googleapiclient.discovery_cache:file_cache is unavailable when using oauth2client >= 4.0.0
Traceback (most recent call last):
  File "C:\Program Files (x86)\Python\Python-3.5.2\lib\site-packages\googleapiclient\discovery_cache\__init__.py", line 36, in autodetect
    from google.appengine.api import memcache
ImportError: No module named 'google'

During handling of the above exception, another exception occurred:

Traceback (most recent call last):
  File "C:\Program Files (x86)\Python\Python-3.5.2\lib\site-packages\googleapiclient\discovery_cache\file_cache.py", line 33, in <module>
    from oauth2client.contrib.locked_file import LockedFile
ImportError: No module named 'oauth2client.contrib.locked_file'

During handling of the above exception, another exception occurred:

Traceback (most recent call last):
  File "C:\Program Files (x86)\Python\Python-3.5.2\lib\site-packages\googleapiclient\discovery_cache\file_cache.py", line 37, in <module>
    from oauth2client.locked_file import LockedFile
ImportError: No module named 'oauth2client.locked_file'

During handling of the above exception, another exception occurred:

Traceback (most recent call last):
  File "C:\Program Files (x86)\Python\Python-3.5.2\lib\site-packages\googleapiclient\discovery_cache\__init__.py", line 41, in autodetect
    from . import file_cache
  File "C:\Program Files (x86)\Python\Python-3.5.2\lib\site-packages\googleapiclient\discovery_cache\file_cache.py", line 41, in <module>
    'file_cache is unavailable when using oauth2client >= 4.0.0')
ImportError: file_cache is unavailable when using oauth2client >= 4.0.0
INFO:googleapiclient.discovery:URL being requested: GET https://www.googleapis.com/discovery/v1/apis/calendar/v3/rest
INFO:googleapiclient.discovery:URL being requested: GET https://www.googleapis.com/calendar/v3/calendars/g0tostl4q2q8dc3kblkqtuuv6g%40group.calendar.google.com/events?alt=json&maxResults=5&singleEvents=true&orderBy=startTime&timeMin=2016-12-08T11%3A08%3A48.680145Z
INFO:googleapiclient.discovery:URL being requested: GET https://www.googleapis.com/calendar/v3/calendars/4dg6pu1jnusdpnkump4frglocs%40group.calendar.google.com/events?alt=json&maxResults=5&singleEvents=true&orderBy=startTime&timeMin=2016-12-08T11%3A08%3A48.680145Z
INFO:googleapiclient.discovery:URL being requested: GET https://www.googleapis.com/calendar/v3/calendars/8jaema1ucgrt3g03fjuv8r5smk%40group.calendar.google.com/events?alt=json&maxResults=5&singleEvents=true&orderBy=startTime&timeMin=2016-12-08T11%3A08%3A48.680145Z
INFO:googleapiclient.discovery:URL being requested: GET https://www.googleapis.com/calendar/v3/calendars/euokutpi37i11v0h3igns7fjh4%40group.calendar.google.com/events?alt=json&maxResults=5&singleEvents=true&orderBy=startTime&timeMin=2016-12-08T11%3A08%3A48.680145Z
WARNING:googleapiclient.discovery_cache:file_cache is unavailable when using oauth2client >= 4.0.0
Traceback (most recent call last):
  File "C:\Program Files (x86)\Python\Python-3.5.2\lib\site-packages\googleapiclient\discovery_cache\__init__.py", line 36, in autodetect
    from google.appengine.api import memcache
ImportError: No module named 'google'

During handling of the above exception, another exception occurred:

Traceback (most recent call last):
  File "C:\Program Files (x86)\Python\Python-3.5.2\lib\site-packages\googleapiclient\discovery_cache\file_cache.py", line 33, in <module>
    from oauth2client.contrib.locked_file import LockedFile
ImportError: No module named 'oauth2client.contrib.locked_file'

During handling of the above exception, another exception occurred:

Traceback (most recent call last):
  File "C:\Program Files (x86)\Python\Python-3.5.2\lib\site-packages\googleapiclient\discovery_cache\file_cache.py", line 37, in <module>
    from oauth2client.locked_file import LockedFile
ImportError: No module named 'oauth2client.locked_file'

During handling of the above exception, another exception occurred:

Traceback (most recent call last):
  File "C:\Program Files (x86)\Python\Python-3.5.2\lib\site-packages\googleapiclient\discovery_cache\__init__.py", line 41, in autodetect
    from . import file_cache
  File "C:\Program Files (x86)\Python\Python-3.5.2\lib\site-packages\googleapiclient\discovery_cache\file_cache.py", line 41, in <module>
    'file_cache is unavailable when using oauth2client >= 4.0.0')
ImportError: file_cache is unavailable when using oauth2client >= 4.0.0
INFO:googleapiclient.discovery:URL being requested: GET https://www.googleapis.com/discovery/v1/apis/calendar/v3/rest
INFO:googleapiclient.discovery:URL being requested: GET https://www.googleapis.com/calendar/v3/calendars/g0tostl4q2q8dc3kblkqtuuv6g%40group.calendar.google.com/events?alt=json&maxResults=5&singleEvents=true&orderBy=startTime&timeMin=2016-12-08T11%3A08%3A49.589612Z
INFO:googleapiclient.discovery:URL being requested: GET https://www.googleapis.com/calendar/v3/calendars/4dg6pu1jnusdpnkump4frglocs%40group.calendar.google.com/events?alt=json&maxResults=5&singleEvents=true&orderBy=startTime&timeMin=2016-12-08T11%3A08%3A49.589612Z
INFO:googleapiclient.discovery:URL being requested: GET https://www.googleapis.com/calendar/v3/calendars/8jaema1ucgrt3g03fjuv8r5smk%40group.calendar.google.com/events?alt=json&maxResults=5&singleEvents=true&orderBy=startTime&timeMin=2016-12-08T11%3A08%3A49.589612Z
INFO:googleapiclient.discovery:URL being requested: GET https://www.googleapis.com/calendar/v3/calendars/euokutpi37i11v0h3igns7fjh4%40group.calendar.google.com/events?alt=json&maxResults=5&singleEvents=true&orderBy=startTime&timeMin=2016-12-08T11%3A08%3A49.589612Z
WARNING:googleapiclient.discovery_cache:file_cache is unavailable when using oauth2client >= 4.0.0
Traceback (most recent call last):
  File "C:\Program Files (x86)\Python\Python-3.5.2\lib\site-packages\googleapiclient\discovery_cache\__init__.py", line 36, in autodetect
    from google.appengine.api import memcache
ImportError: No module named 'google'

During handling of the above exception, another exception occurred:

Traceback (most recent call last):
  File "C:\Program Files (x86)\Python\Python-3.5.2\lib\site-packages\googleapiclient\discovery_cache\file_cache.py", line 33, in <module>
    from oauth2client.contrib.locked_file import LockedFile
ImportError: No module named 'oauth2client.contrib.locked_file'

During handling of the above exception, another exception occurred:

Traceback (most recent call last):
  File "C:\Program Files (x86)\Python\Python-3.5.2\lib\site-packages\googleapiclient\discovery_cache\file_cache.py", line 37, in <module>
    from oauth2client.locked_file import LockedFile
ImportError: No module named 'oauth2client.locked_file'

During handling of the above exception, another exception occurred:

Traceback (most recent call last):
  File "C:\Program Files (x86)\Python\Python-3.5.2\lib\site-packages\googleapiclient\discovery_cache\__init__.py", line 41, in autodetect
    from . import file_cache
  File "C:\Program Files (x86)\Python\Python-3.5.2\lib\site-packages\googleapiclient\discovery_cache\file_cache.py", line 41, in <module>
    'file_cache is unavailable when using oauth2client >= 4.0.0')
ImportError: file_cache is unavailable when using oauth2client >= 4.0.0
INFO:googleapiclient.discovery:URL being requested: GET https://www.googleapis.com/discovery/v1/apis/calendar/v3/rest
INFO:googleapiclient.discovery:URL being requested: GET https://www.googleapis.com/calendar/v3/calendars/g0tostl4q2q8dc3kblkqtuuv6g%40group.calendar.google.com/events?timeMin=2016-12-08T11%3A34%3A53.808430Z&maxResults=5&orderBy=startTime&alt=json&singleEvents=true
INFO:googleapiclient.discovery:URL being requested: GET https://www.googleapis.com/calendar/v3/calendars/4dg6pu1jnusdpnkump4frglocs%40group.calendar.google.com/events?timeMin=2016-12-08T11%3A34%3A53.808430Z&maxResults=5&orderBy=startTime&alt=json&singleEvents=true
INFO:googleapiclient.discovery:URL being requested: GET https://www.googleapis.com/calendar/v3/calendars/8jaema1ucgrt3g03fjuv8r5smk%40group.calendar.google.com/events?timeMin=2016-12-08T11%3A34%3A53.808430Z&maxResults=5&orderBy=startTime&alt=json&singleEvents=true
INFO:googleapiclient.discovery:URL being requested: GET https://www.googleapis.com/calendar/v3/calendars/euokutpi37i11v0h3igns7fjh4%40group.calendar.google.com/events?timeMin=2016-12-08T11%3A34%3A53.808430Z&maxResults=5&orderBy=startTime&alt=json&singleEvents=true
WARNING:googleapiclient.discovery_cache:file_cache is unavailable when using oauth2client >= 4.0.0
Traceback (most recent call last):
  File "C:\Program Files (x86)\Python\Python-3.5.2\lib\site-packages\googleapiclient\discovery_cache\__init__.py", line 36, in autodetect
    from google.appengine.api import memcache
ImportError: No module named 'google'

During handling of the above exception, another exception occurred:

Traceback (most recent call last):
  File "C:\Program Files (x86)\Python\Python-3.5.2\lib\site-packages\googleapiclient\discovery_cache\file_cache.py", line 33, in <module>
    from oauth2client.contrib.locked_file import LockedFile
ImportError: No module named 'oauth2client.contrib.locked_file'

During handling of the above exception, another exception occurred:

Traceback (most recent call last):
  File "C:\Program Files (x86)\Python\Python-3.5.2\lib\site-packages\googleapiclient\discovery_cache\file_cache.py", line 37, in <module>
    from oauth2client.locked_file import LockedFile
ImportError: No module named 'oauth2client.locked_file'

During handling of the above exception, another exception occurred:

Traceback (most recent call last):
  File "C:\Program Files (x86)\Python\Python-3.5.2\lib\site-packages\googleapiclient\discovery_cache\__init__.py", line 41, in autodetect
    from . import file_cache
  File "C:\Program Files (x86)\Python\Python-3.5.2\lib\site-packages\googleapiclient\discovery_cache\file_cache.py", line 41, in <module>
    'file_cache is unavailable when using oauth2client >= 4.0.0')
ImportError: file_cache is unavailable when using oauth2client >= 4.0.0
INFO:googleapiclient.discovery:URL being requested: GET https://www.googleapis.com/discovery/v1/apis/calendar/v3/rest
INFO:googleapiclient.discovery:URL being requested: GET https://www.googleapis.com/calendar/v3/calendars/g0tostl4q2q8dc3kblkqtuuv6g%40group.calendar.google.com/events?maxResults=5&timeMin=2016-12-08T12%3A04%3A17.901004Z&singleEvents=true&alt=json&orderBy=startTime
INFO:googleapiclient.discovery:URL being requested: GET https://www.googleapis.com/calendar/v3/calendars/4dg6pu1jnusdpnkump4frglocs%40group.calendar.google.com/events?maxResults=5&timeMin=2016-12-08T12%3A04%3A17.901004Z&singleEvents=true&alt=json&orderBy=startTime
INFO:googleapiclient.discovery:URL being requested: GET https://www.googleapis.com/calendar/v3/calendars/8jaema1ucgrt3g03fjuv8r5smk%40group.calendar.google.com/events?maxResults=5&timeMin=2016-12-08T12%3A04%3A17.901004Z&singleEvents=true&alt=json&orderBy=startTime
INFO:googleapiclient.discovery:URL being requested: GET https://www.googleapis.com/calendar/v3/calendars/euokutpi37i11v0h3igns7fjh4%40group.calendar.google.com/events?maxResults=5&timeMin=2016-12-08T12%3A04%3A17.901004Z&singleEvents=true&alt=json&orderBy=startTime
WARNING:googleapiclient.discovery_cache:file_cache is unavailable when using oauth2client >= 4.0.0
Traceback (most recent call last):
  File "C:\Program Files (x86)\Python\Python-3.5.2\lib\site-packages\googleapiclient\discovery_cache\__init__.py", line 36, in autodetect
    from google.appengine.api import memcache
ImportError: No module named 'google'

During handling of the above exception, another exception occurred:

Traceback (most recent call last):
  File "C:\Program Files (x86)\Python\Python-3.5.2\lib\site-packages\googleapiclient\discovery_cache\file_cache.py", line 33, in <module>
    from oauth2client.contrib.locked_file import LockedFile
ImportError: No module named 'oauth2client.contrib.locked_file'

During handling of the above exception, another exception occurred:

Traceback (most recent call last):
  File "C:\Program Files (x86)\Python\Python-3.5.2\lib\site-packages\googleapiclient\discovery_cache\file_cache.py", line 37, in <module>
    from oauth2client.locked_file import LockedFile
ImportError: No module named 'oauth2client.locked_file'

During handling of the above exception, another exception occurred:

Traceback (most recent call last):
  File "C:\Program Files (x86)\Python\Python-3.5.2\lib\site-packages\googleapiclient\discovery_cache\__init__.py", line 41, in autodetect
    from . import file_cache
  File "C:\Program Files (x86)\Python\Python-3.5.2\lib\site-packages\googleapiclient\discovery_cache\file_cache.py", line 41, in <module>
    'file_cache is unavailable when using oauth2client >= 4.0.0')
ImportError: file_cache is unavailable when using oauth2client >= 4.0.0
INFO:googleapiclient.discovery:URL being requested: GET https://www.googleapis.com/discovery/v1/apis/calendar/v3/rest
INFO:googleapiclient.discovery:URL being requested: GET https://www.googleapis.com/calendar/v3/calendars/g0tostl4q2q8dc3kblkqtuuv6g%40group.calendar.google.com/events?maxResults=5&timeMin=2016-12-08T12%3A04%3A47.927061Z&singleEvents=true&alt=json&orderBy=startTime
INFO:googleapiclient.discovery:URL being requested: GET https://www.googleapis.com/calendar/v3/calendars/4dg6pu1jnusdpnkump4frglocs%40group.calendar.google.com/events?maxResults=5&timeMin=2016-12-08T12%3A04%3A47.927061Z&singleEvents=true&alt=json&orderBy=startTime
INFO:googleapiclient.discovery:URL being requested: GET https://www.googleapis.com/calendar/v3/calendars/8jaema1ucgrt3g03fjuv8r5smk%40group.calendar.google.com/events?maxResults=5&timeMin=2016-12-08T12%3A04%3A47.927061Z&singleEvents=true&alt=json&orderBy=startTime
INFO:googleapiclient.discovery:URL being requested: GET https://www.googleapis.com/calendar/v3/calendars/euokutpi37i11v0h3igns7fjh4%40group.calendar.google.com/events?maxResults=5&timeMin=2016-12-08T12%3A04%3A47.927061Z&singleEvents=true&alt=json&orderBy=startTime
WARNING:googleapiclient.discovery_cache:file_cache is unavailable when using oauth2client >= 4.0.0
Traceback (most recent call last):
  File "C:\Program Files (x86)\Python\Python-3.5.2\lib\site-packages\googleapiclient\discovery_cache\__init__.py", line 36, in autodetect
    from google.appengine.api import memcache
ImportError: No module named 'google'

During handling of the above exception, another exception occurred:

Traceback (most recent call last):
  File "C:\Program Files (x86)\Python\Python-3.5.2\lib\site-packages\googleapiclient\discovery_cache\file_cache.py", line 33, in <module>
    from oauth2client.contrib.locked_file import LockedFile
ImportError: No module named 'oauth2client.contrib.locked_file'

During handling of the above exception, another exception occurred:

Traceback (most recent call last):
  File "C:\Program Files (x86)\Python\Python-3.5.2\lib\site-packages\googleapiclient\discovery_cache\file_cache.py", line 37, in <module>
    from oauth2client.locked_file import LockedFile
ImportError: No module named 'oauth2client.locked_file'

During handling of the above exception, another exception occurred:

Traceback (most recent call last):
  File "C:\Program Files (x86)\Python\Python-3.5.2\lib\site-packages\googleapiclient\discovery_cache\__init__.py", line 41, in autodetect
    from . import file_cache
  File "C:\Program Files (x86)\Python\Python-3.5.2\lib\site-packages\googleapiclient\discovery_cache\file_cache.py", line 41, in <module>
    'file_cache is unavailable when using oauth2client >= 4.0.0')
ImportError: file_cache is unavailable when using oauth2client >= 4.0.0
INFO:googleapiclient.discovery:URL being requested: GET https://www.googleapis.com/discovery/v1/apis/calendar/v3/rest
INFO:googleapiclient.discovery:URL being requested: GET https://www.googleapis.com/calendar/v3/calendars/g0tostl4q2q8dc3kblkqtuuv6g%40group.calendar.google.com/events?maxResults=5&timeMin=2016-12-08T12%3A04%3A48.855879Z&singleEvents=true&alt=json&orderBy=startTime
INFO:googleapiclient.discovery:URL being requested: GET https://www.googleapis.com/calendar/v3/calendars/4dg6pu1jnusdpnkump4frglocs%40group.calendar.google.com/events?maxResults=5&timeMin=2016-12-08T12%3A04%3A48.855879Z&singleEvents=true&alt=json&orderBy=startTime
INFO:googleapiclient.discovery:URL being requested: GET https://www.googleapis.com/calendar/v3/calendars/8jaema1ucgrt3g03fjuv8r5smk%40group.calendar.google.com/events?maxResults=5&timeMin=2016-12-08T12%3A04%3A48.855879Z&singleEvents=true&alt=json&orderBy=startTime
INFO:googleapiclient.discovery:URL being requested: GET https://www.googleapis.com/calendar/v3/calendars/euokutpi37i11v0h3igns7fjh4%40group.calendar.google.com/events?maxResults=5&timeMin=2016-12-08T12%3A04%3A48.855879Z&singleEvents=true&alt=json&orderBy=startTime
WARNING:googleapiclient.discovery_cache:file_cache is unavailable when using oauth2client >= 4.0.0
Traceback (most recent call last):
  File "C:\Program Files (x86)\Python\Python-3.5.2\lib\site-packages\googleapiclient\discovery_cache\__init__.py", line 36, in autodetect
    from google.appengine.api import memcache
ImportError: No module named 'google'

During handling of the above exception, another exception occurred:

Traceback (most recent call last):
  File "C:\Program Files (x86)\Python\Python-3.5.2\lib\site-packages\googleapiclient\discovery_cache\file_cache.py", line 33, in <module>
    from oauth2client.contrib.locked_file import LockedFile
ImportError: No module named 'oauth2client.contrib.locked_file'

During handling of the above exception, another exception occurred:

Traceback (most recent call last):
  File "C:\Program Files (x86)\Python\Python-3.5.2\lib\site-packages\googleapiclient\discovery_cache\file_cache.py", line 37, in <module>
    from oauth2client.locked_file import LockedFile
ImportError: No module named 'oauth2client.locked_file'

During handling of the above exception, another exception occurred:

Traceback (most recent call last):
  File "C:\Program Files (x86)\Python\Python-3.5.2\lib\site-packages\googleapiclient\discovery_cache\__init__.py", line 41, in autodetect
    from . import file_cache
  File "C:\Program Files (x86)\Python\Python-3.5.2\lib\site-packages\googleapiclient\discovery_cache\file_cache.py", line 41, in <module>
    'file_cache is unavailable when using oauth2client >= 4.0.0')
ImportError: file_cache is unavailable when using oauth2client >= 4.0.0
INFO:googleapiclient.discovery:URL being requested: GET https://www.googleapis.com/discovery/v1/apis/calendar/v3/rest
INFO:googleapiclient.discovery:URL being requested: GET https://www.googleapis.com/calendar/v3/calendars/g0tostl4q2q8dc3kblkqtuuv6g%40group.calendar.google.com/events?maxResults=5&timeMin=2016-12-08T12%3A04%3A49.778075Z&singleEvents=true&alt=json&orderBy=startTime
INFO:googleapiclient.discovery:URL being requested: GET https://www.googleapis.com/calendar/v3/calendars/4dg6pu1jnusdpnkump4frglocs%40group.calendar.google.com/events?maxResults=5&timeMin=2016-12-08T12%3A04%3A49.778075Z&singleEvents=true&alt=json&orderBy=startTime
INFO:googleapiclient.discovery:URL being requested: GET https://www.googleapis.com/calendar/v3/calendars/8jaema1ucgrt3g03fjuv8r5smk%40group.calendar.google.com/events?maxResults=5&timeMin=2016-12-08T12%3A04%3A49.778075Z&singleEvents=true&alt=json&orderBy=startTime
INFO:googleapiclient.discovery:URL being requested: GET https://www.googleapis.com/calendar/v3/calendars/euokutpi37i11v0h3igns7fjh4%40group.calendar.google.com/events?maxResults=5&timeMin=2016-12-08T12%3A04%3A49.778075Z&singleEvents=true&alt=json&orderBy=startTime
WARNING:googleapiclient.discovery_cache:file_cache is unavailable when using oauth2client >= 4.0.0
Traceback (most recent call last):
  File "C:\Program Files (x86)\Python\Python-3.5.2\lib\site-packages\googleapiclient\discovery_cache\__init__.py", line 36, in autodetect
    from google.appengine.api import memcache
ImportError: No module named 'google'

During handling of the above exception, another exception occurred:

Traceback (most recent call last):
  File "C:\Program Files (x86)\Python\Python-3.5.2\lib\site-packages\googleapiclient\discovery_cache\file_cache.py", line 33, in <module>
    from oauth2client.contrib.locked_file import LockedFile
ImportError: No module named 'oauth2client.contrib.locked_file'

During handling of the above exception, another exception occurred:

Traceback (most recent call last):
  File "C:\Program Files (x86)\Python\Python-3.5.2\lib\site-packages\googleapiclient\discovery_cache\file_cache.py", line 37, in <module>
    from oauth2client.locked_file import LockedFile
ImportError: No module named 'oauth2client.locked_file'

During handling of the above exception, another exception occurred:

Traceback (most recent call last):
  File "C:\Program Files (x86)\Python\Python-3.5.2\lib\site-packages\googleapiclient\discovery_cache\__init__.py", line 41, in autodetect
    from . import file_cache
  File "C:\Program Files (x86)\Python\Python-3.5.2\lib\site-packages\googleapiclient\discovery_cache\file_cache.py", line 41, in <module>
    'file_cache is unavailable when using oauth2client >= 4.0.0')
ImportError: file_cache is unavailable when using oauth2client >= 4.0.0
INFO:googleapiclient.discovery:URL being requested: GET https://www.googleapis.com/discovery/v1/apis/calendar/v3/rest
INFO:googleapiclient.discovery:URL being requested: GET https://www.googleapis.com/calendar/v3/calendars/g0tostl4q2q8dc3kblkqtuuv6g%40group.calendar.google.com/events?singleEvents=true&orderBy=startTime&alt=json&maxResults=5&timeMin=2016-12-08T12%3A13%3A33.186199Z
INFO:googleapiclient.discovery:URL being requested: GET https://www.googleapis.com/calendar/v3/calendars/4dg6pu1jnusdpnkump4frglocs%40group.calendar.google.com/events?singleEvents=true&orderBy=startTime&alt=json&maxResults=5&timeMin=2016-12-08T12%3A13%3A33.186199Z
INFO:googleapiclient.discovery:URL being requested: GET https://www.googleapis.com/calendar/v3/calendars/8jaema1ucgrt3g03fjuv8r5smk%40group.calendar.google.com/events?singleEvents=true&orderBy=startTime&alt=json&maxResults=5&timeMin=2016-12-08T12%3A13%3A33.186199Z
INFO:googleapiclient.discovery:URL being requested: GET https://www.googleapis.com/calendar/v3/calendars/euokutpi37i11v0h3igns7fjh4%40group.calendar.google.com/events?singleEvents=true&orderBy=startTime&alt=json&maxResults=5&timeMin=2016-12-08T12%3A13%3A33.186199Z
WARNING:googleapiclient.discovery_cache:file_cache is unavailable when using oauth2client >= 4.0.0
Traceback (most recent call last):
  File "C:\Program Files (x86)\Python\Python-3.5.2\lib\site-packages\googleapiclient\discovery_cache\__init__.py", line 36, in autodetect
    from google.appengine.api import memcache
ImportError: No module named 'google'

During handling of the above exception, another exception occurred:

Traceback (most recent call last):
  File "C:\Program Files (x86)\Python\Python-3.5.2\lib\site-packages\googleapiclient\discovery_cache\file_cache.py", line 33, in <module>
    from oauth2client.contrib.locked_file import LockedFile
ImportError: No module named 'oauth2client.contrib.locked_file'

During handling of the above exception, another exception occurred:

Traceback (most recent call last):
  File "C:\Program Files (x86)\Python\Python-3.5.2\lib\site-packages\googleapiclient\discovery_cache\file_cache.py", line 37, in <module>
    from oauth2client.locked_file import LockedFile
ImportError: No module named 'oauth2client.locked_file'

During handling of the above exception, another exception occurred:

Traceback (most recent call last):
  File "C:\Program Files (x86)\Python\Python-3.5.2\lib\site-packages\googleapiclient\discovery_cache\__init__.py", line 41, in autodetect
    from . import file_cache
  File "C:\Program Files (x86)\Python\Python-3.5.2\lib\site-packages\googleapiclient\discovery_cache\file_cache.py", line 41, in <module>
    'file_cache is unavailable when using oauth2client >= 4.0.0')
ImportError: file_cache is unavailable when using oauth2client >= 4.0.0
INFO:googleapiclient.discovery:URL being requested: GET https://www.googleapis.com/discovery/v1/apis/calendar/v3/rest
INFO:googleapiclient.discovery:URL being requested: GET https://www.googleapis.com/calendar/v3/calendars/g0tostl4q2q8dc3kblkqtuuv6g%40group.calendar.google.com/events?singleEvents=true&orderBy=startTime&alt=json&maxResults=5&timeMin=2016-12-08T12%3A13%3A51.446816Z
INFO:googleapiclient.discovery:URL being requested: GET https://www.googleapis.com/calendar/v3/calendars/4dg6pu1jnusdpnkump4frglocs%40group.calendar.google.com/events?singleEvents=true&orderBy=startTime&alt=json&maxResults=5&timeMin=2016-12-08T12%3A13%3A51.446816Z
INFO:googleapiclient.discovery:URL being requested: GET https://www.googleapis.com/calendar/v3/calendars/8jaema1ucgrt3g03fjuv8r5smk%40group.calendar.google.com/events?singleEvents=true&orderBy=startTime&alt=json&maxResults=5&timeMin=2016-12-08T12%3A13%3A51.446816Z
INFO:googleapiclient.discovery:URL being requested: GET https://www.googleapis.com/calendar/v3/calendars/euokutpi37i11v0h3igns7fjh4%40group.calendar.google.com/events?singleEvents=true&orderBy=startTime&alt=json&maxResults=5&timeMin=2016-12-08T12%3A13%3A51.446816Z
WARNING:googleapiclient.discovery_cache:file_cache is unavailable when using oauth2client >= 4.0.0
Traceback (most recent call last):
  File "C:\Program Files (x86)\Python\Python-3.5.2\lib\site-packages\googleapiclient\discovery_cache\__init__.py", line 36, in autodetect
    from google.appengine.api import memcache
ImportError: No module named 'google'

During handling of the above exception, another exception occurred:

Traceback (most recent call last):
  File "C:\Program Files (x86)\Python\Python-3.5.2\lib\site-packages\googleapiclient\discovery_cache\file_cache.py", line 33, in <module>
    from oauth2client.contrib.locked_file import LockedFile
ImportError: No module named 'oauth2client.contrib.locked_file'

During handling of the above exception, another exception occurred:

Traceback (most recent call last):
  File "C:\Program Files (x86)\Python\Python-3.5.2\lib\site-packages\googleapiclient\discovery_cache\file_cache.py", line 37, in <module>
    from oauth2client.locked_file import LockedFile
ImportError: No module named 'oauth2client.locked_file'

During handling of the above exception, another exception occurred:

Traceback (most recent call last):
  File "C:\Program Files (x86)\Python\Python-3.5.2\lib\site-packages\googleapiclient\discovery_cache\__init__.py", line 41, in autodetect
    from . import file_cache
  File "C:\Program Files (x86)\Python\Python-3.5.2\lib\site-packages\googleapiclient\discovery_cache\file_cache.py", line 41, in <module>
    'file_cache is unavailable when using oauth2client >= 4.0.0')
ImportError: file_cache is unavailable when using oauth2client >= 4.0.0
INFO:googleapiclient.discovery:URL being requested: GET https://www.googleapis.com/discovery/v1/apis/calendar/v3/rest
INFO:googleapiclient.discovery:URL being requested: GET https://www.googleapis.com/calendar/v3/calendars/g0tostl4q2q8dc3kblkqtuuv6g%40group.calendar.google.com/events?singleEvents=true&orderBy=startTime&alt=json&maxResults=5&timeMin=2016-12-08T12%3A13%3A52.375416Z
INFO:googleapiclient.discovery:URL being requested: GET https://www.googleapis.com/calendar/v3/calendars/4dg6pu1jnusdpnkump4frglocs%40group.calendar.google.com/events?singleEvents=true&orderBy=startTime&alt=json&maxResults=5&timeMin=2016-12-08T12%3A13%3A52.375416Z
INFO:googleapiclient.discovery:URL being requested: GET https://www.googleapis.com/calendar/v3/calendars/8jaema1ucgrt3g03fjuv8r5smk%40group.calendar.google.com/events?singleEvents=true&orderBy=startTime&alt=json&maxResults=5&timeMin=2016-12-08T12%3A13%3A52.375416Z
INFO:googleapiclient.discovery:URL being requested: GET https://www.googleapis.com/calendar/v3/calendars/euokutpi37i11v0h3igns7fjh4%40group.calendar.google.com/events?singleEvents=true&orderBy=startTime&alt=json&maxResults=5&timeMin=2016-12-08T12%3A13%3A52.375416Z
WARNING:googleapiclient.discovery_cache:file_cache is unavailable when using oauth2client >= 4.0.0
Traceback (most recent call last):
  File "C:\Program Files (x86)\Python\Python-3.5.2\lib\site-packages\googleapiclient\discovery_cache\__init__.py", line 36, in autodetect
    from google.appengine.api import memcache
ImportError: No module named 'google'

During handling of the above exception, another exception occurred:

Traceback (most recent call last):
  File "C:\Program Files (x86)\Python\Python-3.5.2\lib\site-packages\googleapiclient\discovery_cache\file_cache.py", line 33, in <module>
    from oauth2client.contrib.locked_file import LockedFile
ImportError: No module named 'oauth2client.contrib.locked_file'

During handling of the above exception, another exception occurred:

Traceback (most recent call last):
  File "C:\Program Files (x86)\Python\Python-3.5.2\lib\site-packages\googleapiclient\discovery_cache\file_cache.py", line 37, in <module>
    from oauth2client.locked_file import LockedFile
ImportError: No module named 'oauth2client.locked_file'

During handling of the above exception, another exception occurred:

Traceback (most recent call last):
  File "C:\Program Files (x86)\Python\Python-3.5.2\lib\site-packages\googleapiclient\discovery_cache\__init__.py", line 41, in autodetect
    from . import file_cache
  File "C:\Program Files (x86)\Python\Python-3.5.2\lib\site-packages\googleapiclient\discovery_cache\file_cache.py", line 41, in <module>
    'file_cache is unavailable when using oauth2client >= 4.0.0')
ImportError: file_cache is unavailable when using oauth2client >= 4.0.0
INFO:googleapiclient.discovery:URL being requested: GET https://www.googleapis.com/discovery/v1/apis/calendar/v3/rest
INFO:googleapiclient.discovery:URL being requested: GET https://www.googleapis.com/calendar/v3/calendars/g0tostl4q2q8dc3kblkqtuuv6g%40group.calendar.google.com/events?singleEvents=true&orderBy=startTime&alt=json&maxResults=5&timeMin=2016-12-08T12%3A13%3A53.574685Z
INFO:googleapiclient.discovery:URL being requested: GET https://www.googleapis.com/calendar/v3/calendars/4dg6pu1jnusdpnkump4frglocs%40group.calendar.google.com/events?singleEvents=true&orderBy=startTime&alt=json&maxResults=5&timeMin=2016-12-08T12%3A13%3A53.574685Z
INFO:googleapiclient.discovery:URL being requested: GET https://www.googleapis.com/calendar/v3/calendars/8jaema1ucgrt3g03fjuv8r5smk%40group.calendar.google.com/events?singleEvents=true&orderBy=startTime&alt=json&maxResults=5&timeMin=2016-12-08T12%3A13%3A53.574685Z
INFO:googleapiclient.discovery:URL being requested: GET https://www.googleapis.com/calendar/v3/calendars/euokutpi37i11v0h3igns7fjh4%40group.calendar.google.com/events?singleEvents=true&orderBy=startTime&alt=json&maxResults=5&timeMin=2016-12-08T12%3A13%3A53.574685Z
WARNING:googleapiclient.discovery_cache:file_cache is unavailable when using oauth2client >= 4.0.0
Traceback (most recent call last):
  File "C:\Program Files (x86)\Python\Python-3.5.2\lib\site-packages\googleapiclient\discovery_cache\__init__.py", line 36, in autodetect
    from google.appengine.api import memcache
ImportError: No module named 'google'

During handling of the above exception, another exception occurred:

Traceback (most recent call last):
  File "C:\Program Files (x86)\Python\Python-3.5.2\lib\site-packages\googleapiclient\discovery_cache\file_cache.py", line 33, in <module>
    from oauth2client.contrib.locked_file import LockedFile
ImportError: No module named 'oauth2client.contrib.locked_file'

During handling of the above exception, another exception occurred:

Traceback (most recent call last):
  File "C:\Program Files (x86)\Python\Python-3.5.2\lib\site-packages\googleapiclient\discovery_cache\file_cache.py", line 37, in <module>
    from oauth2client.locked_file import LockedFile
ImportError: No module named 'oauth2client.locked_file'

During handling of the above exception, another exception occurred:

Traceback (most recent call last):
  File "C:\Program Files (x86)\Python\Python-3.5.2\lib\site-packages\googleapiclient\discovery_cache\__init__.py", line 41, in autodetect
    from . import file_cache
  File "C:\Program Files (x86)\Python\Python-3.5.2\lib\site-packages\googleapiclient\discovery_cache\file_cache.py", line 41, in <module>
    'file_cache is unavailable when using oauth2client >= 4.0.0')
ImportError: file_cache is unavailable when using oauth2client >= 4.0.0
INFO:googleapiclient.discovery:URL being requested: GET https://www.googleapis.com/discovery/v1/apis/calendar/v3/rest
INFO:googleapiclient.discovery:URL being requested: GET https://www.googleapis.com/calendar/v3/calendars/g0tostl4q2q8dc3kblkqtuuv6g%40group.calendar.google.com/events?timeMin=2016-12-08T12%3A19%3A03.828991Z&alt=json&maxResults=5&orderBy=startTime&singleEvents=true
INFO:googleapiclient.discovery:URL being requested: GET https://www.googleapis.com/calendar/v3/calendars/4dg6pu1jnusdpnkump4frglocs%40group.calendar.google.com/events?timeMin=2016-12-08T12%3A19%3A03.828991Z&alt=json&maxResults=5&orderBy=startTime&singleEvents=true
INFO:googleapiclient.discovery:URL being requested: GET https://www.googleapis.com/calendar/v3/calendars/8jaema1ucgrt3g03fjuv8r5smk%40group.calendar.google.com/events?timeMin=2016-12-08T12%3A19%3A03.828991Z&alt=json&maxResults=5&orderBy=startTime&singleEvents=true
INFO:googleapiclient.discovery:URL being requested: GET https://www.googleapis.com/calendar/v3/calendars/euokutpi37i11v0h3igns7fjh4%40group.calendar.google.com/events?timeMin=2016-12-08T12%3A19%3A03.828991Z&alt=json&maxResults=5&orderBy=startTime&singleEvents=true
WARNING:googleapiclient.discovery_cache:file_cache is unavailable when using oauth2client >= 4.0.0
Traceback (most recent call last):
  File "C:\Program Files (x86)\Python\Python-3.5.2\lib\site-packages\googleapiclient\discovery_cache\__init__.py", line 36, in autodetect
    from google.appengine.api import memcache
ImportError: No module named 'google'

During handling of the above exception, another exception occurred:

Traceback (most recent call last):
  File "C:\Program Files (x86)\Python\Python-3.5.2\lib\site-packages\googleapiclient\discovery_cache\file_cache.py", line 33, in <module>
    from oauth2client.contrib.locked_file import LockedFile
ImportError: No module named 'oauth2client.contrib.locked_file'

During handling of the above exception, another exception occurred:

Traceback (most recent call last):
  File "C:\Program Files (x86)\Python\Python-3.5.2\lib\site-packages\googleapiclient\discovery_cache\file_cache.py", line 37, in <module>
    from oauth2client.locked_file import LockedFile
ImportError: No module named 'oauth2client.locked_file'

During handling of the above exception, another exception occurred:

Traceback (most recent call last):
  File "C:\Program Files (x86)\Python\Python-3.5.2\lib\site-packages\googleapiclient\discovery_cache\__init__.py", line 41, in autodetect
    from . import file_cache
  File "C:\Program Files (x86)\Python\Python-3.5.2\lib\site-packages\googleapiclient\discovery_cache\file_cache.py", line 41, in <module>
    'file_cache is unavailable when using oauth2client >= 4.0.0')
ImportError: file_cache is unavailable when using oauth2client >= 4.0.0
INFO:googleapiclient.discovery:URL being requested: GET https://www.googleapis.com/discovery/v1/apis/calendar/v3/rest
INFO:googleapiclient.discovery:URL being requested: GET https://www.googleapis.com/calendar/v3/calendars/g0tostl4q2q8dc3kblkqtuuv6g%40group.calendar.google.com/events?timeMin=2016-12-08T12%3A19%3A21.075110Z&alt=json&maxResults=5&orderBy=startTime&singleEvents=true
INFO:googleapiclient.discovery:URL being requested: GET https://www.googleapis.com/calendar/v3/calendars/4dg6pu1jnusdpnkump4frglocs%40group.calendar.google.com/events?timeMin=2016-12-08T12%3A19%3A21.075110Z&alt=json&maxResults=5&orderBy=startTime&singleEvents=true
INFO:googleapiclient.discovery:URL being requested: GET https://www.googleapis.com/calendar/v3/calendars/8jaema1ucgrt3g03fjuv8r5smk%40group.calendar.google.com/events?timeMin=2016-12-08T12%3A19%3A21.075110Z&alt=json&maxResults=5&orderBy=startTime&singleEvents=true
INFO:googleapiclient.discovery:URL being requested: GET https://www.googleapis.com/calendar/v3/calendars/euokutpi37i11v0h3igns7fjh4%40group.calendar.google.com/events?timeMin=2016-12-08T12%3A19%3A21.075110Z&alt=json&maxResults=5&orderBy=startTime&singleEvents=true
WARNING:googleapiclient.discovery_cache:file_cache is unavailable when using oauth2client >= 4.0.0
Traceback (most recent call last):
  File "C:\Program Files (x86)\Python\Python-3.5.2\lib\site-packages\googleapiclient\discovery_cache\__init__.py", line 36, in autodetect
    from google.appengine.api import memcache
ImportError: No module named 'google'

During handling of the above exception, another exception occurred:

Traceback (most recent call last):
  File "C:\Program Files (x86)\Python\Python-3.5.2\lib\site-packages\googleapiclient\discovery_cache\file_cache.py", line 33, in <module>
    from oauth2client.contrib.locked_file import LockedFile
ImportError: No module named 'oauth2client.contrib.locked_file'

During handling of the above exception, another exception occurred:

Traceback (most recent call last):
  File "C:\Program Files (x86)\Python\Python-3.5.2\lib\site-packages\googleapiclient\discovery_cache\file_cache.py", line 37, in <module>
    from oauth2client.locked_file import LockedFile
ImportError: No module named 'oauth2client.locked_file'

During handling of the above exception, another exception occurred:

Traceback (most recent call last):
  File "C:\Program Files (x86)\Python\Python-3.5.2\lib\site-packages\googleapiclient\discovery_cache\__init__.py", line 41, in autodetect
    from . import file_cache
  File "C:\Program Files (x86)\Python\Python-3.5.2\lib\site-packages\googleapiclient\discovery_cache\file_cache.py", line 41, in <module>
    'file_cache is unavailable when using oauth2client >= 4.0.0')
ImportError: file_cache is unavailable when using oauth2client >= 4.0.0
INFO:googleapiclient.discovery:URL being requested: GET https://www.googleapis.com/discovery/v1/apis/calendar/v3/rest
INFO:googleapiclient.discovery:URL being requested: GET https://www.googleapis.com/calendar/v3/calendars/g0tostl4q2q8dc3kblkqtuuv6g%40group.calendar.google.com/events?timeMin=2016-12-08T12%3A19%3A22.176104Z&alt=json&maxResults=5&orderBy=startTime&singleEvents=true
INFO:googleapiclient.discovery:URL being requested: GET https://www.googleapis.com/calendar/v3/calendars/4dg6pu1jnusdpnkump4frglocs%40group.calendar.google.com/events?timeMin=2016-12-08T12%3A19%3A22.176104Z&alt=json&maxResults=5&orderBy=startTime&singleEvents=true
INFO:googleapiclient.discovery:URL being requested: GET https://www.googleapis.com/calendar/v3/calendars/8jaema1ucgrt3g03fjuv8r5smk%40group.calendar.google.com/events?timeMin=2016-12-08T12%3A19%3A22.176104Z&alt=json&maxResults=5&orderBy=startTime&singleEvents=true
INFO:googleapiclient.discovery:URL being requested: GET https://www.googleapis.com/calendar/v3/calendars/euokutpi37i11v0h3igns7fjh4%40group.calendar.google.com/events?timeMin=2016-12-08T12%3A19%3A22.176104Z&alt=json&maxResults=5&orderBy=startTime&singleEvents=true
WARNING:googleapiclient.discovery_cache:file_cache is unavailable when using oauth2client >= 4.0.0
Traceback (most recent call last):
  File "C:\Program Files (x86)\Python\Python-3.5.2\lib\site-packages\googleapiclient\discovery_cache\__init__.py", line 36, in autodetect
    from google.appengine.api import memcache
ImportError: No module named 'google'

During handling of the above exception, another exception occurred:

Traceback (most recent call last):
  File "C:\Program Files (x86)\Python\Python-3.5.2\lib\site-packages\googleapiclient\discovery_cache\file_cache.py", line 33, in <module>
    from oauth2client.contrib.locked_file import LockedFile
ImportError: No module named 'oauth2client.contrib.locked_file'

During handling of the above exception, another exception occurred:

Traceback (most recent call last):
  File "C:\Program Files (x86)\Python\Python-3.5.2\lib\site-packages\googleapiclient\discovery_cache\file_cache.py", line 37, in <module>
    from oauth2client.locked_file import LockedFile
ImportError: No module named 'oauth2client.locked_file'

During handling of the above exception, another exception occurred:

Traceback (most recent call last):
  File "C:\Program Files (x86)\Python\Python-3.5.2\lib\site-packages\googleapiclient\discovery_cache\__init__.py", line 41, in autodetect
    from . import file_cache
  File "C:\Program Files (x86)\Python\Python-3.5.2\lib\site-packages\googleapiclient\discovery_cache\file_cache.py", line 41, in <module>
    'file_cache is unavailable when using oauth2client >= 4.0.0')
ImportError: file_cache is unavailable when using oauth2client >= 4.0.0
INFO:googleapiclient.discovery:URL being requested: GET https://www.googleapis.com/discovery/v1/apis/calendar/v3/rest
INFO:googleapiclient.discovery:URL being requested: GET https://www.googleapis.com/calendar/v3/calendars/g0tostl4q2q8dc3kblkqtuuv6g%40group.calendar.google.com/events?timeMin=2016-12-08T12%3A19%3A22.853268Z&alt=json&maxResults=5&orderBy=startTime&singleEvents=true
INFO:googleapiclient.discovery:URL being requested: GET https://www.googleapis.com/calendar/v3/calendars/4dg6pu1jnusdpnkump4frglocs%40group.calendar.google.com/events?timeMin=2016-12-08T12%3A19%3A22.853268Z&alt=json&maxResults=5&orderBy=startTime&singleEvents=true
INFO:googleapiclient.discovery:URL being requested: GET https://www.googleapis.com/calendar/v3/calendars/8jaema1ucgrt3g03fjuv8r5smk%40group.calendar.google.com/events?timeMin=2016-12-08T12%3A19%3A22.853268Z&alt=json&maxResults=5&orderBy=startTime&singleEvents=true
INFO:googleapiclient.discovery:URL being requested: GET https://www.googleapis.com/calendar/v3/calendars/euokutpi37i11v0h3igns7fjh4%40group.calendar.google.com/events?timeMin=2016-12-08T12%3A19%3A22.853268Z&alt=json&maxResults=5&orderBy=startTime&singleEvents=true
WARNING:googleapiclient.discovery_cache:file_cache is unavailable when using oauth2client >= 4.0.0
Traceback (most recent call last):
  File "C:\Program Files (x86)\Python\Python-3.5.2\lib\site-packages\googleapiclient\discovery_cache\__init__.py", line 36, in autodetect
    from google.appengine.api import memcache
ImportError: No module named 'google'

During handling of the above exception, another exception occurred:

Traceback (most recent call last):
  File "C:\Program Files (x86)\Python\Python-3.5.2\lib\site-packages\googleapiclient\discovery_cache\file_cache.py", line 33, in <module>
    from oauth2client.contrib.locked_file import LockedFile
ImportError: No module named 'oauth2client.contrib.locked_file'

During handling of the above exception, another exception occurred:

Traceback (most recent call last):
  File "C:\Program Files (x86)\Python\Python-3.5.2\lib\site-packages\googleapiclient\discovery_cache\file_cache.py", line 37, in <module>
    from oauth2client.locked_file import LockedFile
ImportError: No module named 'oauth2client.locked_file'

During handling of the above exception, another exception occurred:

Traceback (most recent call last):
  File "C:\Program Files (x86)\Python\Python-3.5.2\lib\site-packages\googleapiclient\discovery_cache\__init__.py", line 41, in autodetect
    from . import file_cache
  File "C:\Program Files (x86)\Python\Python-3.5.2\lib\site-packages\googleapiclient\discovery_cache\file_cache.py", line 41, in <module>
    'file_cache is unavailable when using oauth2client >= 4.0.0')
ImportError: file_cache is unavailable when using oauth2client >= 4.0.0
INFO:googleapiclient.discovery:URL being requested: GET https://www.googleapis.com/discovery/v1/apis/calendar/v3/rest
INFO:googleapiclient.discovery:URL being requested: GET https://www.googleapis.com/calendar/v3/calendars/g0tostl4q2q8dc3kblkqtuuv6g%40group.calendar.google.com/events?alt=json&timeMin=2016-12-08T16%3A01%3A38.167816Z&orderBy=startTime&maxResults=5&singleEvents=true
INFO:googleapiclient.discovery:URL being requested: GET https://www.googleapis.com/calendar/v3/calendars/4dg6pu1jnusdpnkump4frglocs%40group.calendar.google.com/events?alt=json&timeMin=2016-12-08T16%3A01%3A38.167816Z&orderBy=startTime&maxResults=5&singleEvents=true
INFO:googleapiclient.discovery:URL being requested: GET https://www.googleapis.com/calendar/v3/calendars/8jaema1ucgrt3g03fjuv8r5smk%40group.calendar.google.com/events?alt=json&timeMin=2016-12-08T16%3A01%3A38.167816Z&orderBy=startTime&maxResults=5&singleEvents=true
INFO:googleapiclient.discovery:URL being requested: GET https://www.googleapis.com/calendar/v3/calendars/euokutpi37i11v0h3igns7fjh4%40group.calendar.google.com/events?alt=json&timeMin=2016-12-08T16%3A01%3A38.167816Z&orderBy=startTime&maxResults=5&singleEvents=true
WARNING:googleapiclient.discovery_cache:file_cache is unavailable when using oauth2client >= 4.0.0
Traceback (most recent call last):
  File "C:\Program Files (x86)\Python\Python-3.5.2\lib\site-packages\googleapiclient\discovery_cache\__init__.py", line 36, in autodetect
    from google.appengine.api import memcache
ImportError: No module named 'google'

During handling of the above exception, another exception occurred:

Traceback (most recent call last):
  File "C:\Program Files (x86)\Python\Python-3.5.2\lib\site-packages\googleapiclient\discovery_cache\file_cache.py", line 33, in <module>
    from oauth2client.contrib.locked_file import LockedFile
ImportError: No module named 'oauth2client.contrib.locked_file'

During handling of the above exception, another exception occurred:

Traceback (most recent call last):
  File "C:\Program Files (x86)\Python\Python-3.5.2\lib\site-packages\googleapiclient\discovery_cache\file_cache.py", line 37, in <module>
    from oauth2client.locked_file import LockedFile
ImportError: No module named 'oauth2client.locked_file'

During handling of the above exception, another exception occurred:

Traceback (most recent call last):
  File "C:\Program Files (x86)\Python\Python-3.5.2\lib\site-packages\googleapiclient\discovery_cache\__init__.py", line 41, in autodetect
    from . import file_cache
  File "C:\Program Files (x86)\Python\Python-3.5.2\lib\site-packages\googleapiclient\discovery_cache\file_cache.py", line 41, in <module>
    'file_cache is unavailable when using oauth2client >= 4.0.0')
ImportError: file_cache is unavailable when using oauth2client >= 4.0.0
INFO:googleapiclient.discovery:URL being requested: GET https://www.googleapis.com/discovery/v1/apis/calendar/v3/rest
INFO:googleapiclient.discovery:URL being requested: GET https://www.googleapis.com/calendar/v3/calendars/g0tostl4q2q8dc3kblkqtuuv6g%40group.calendar.google.com/events?singleEvents=true&alt=json&maxResults=5&timeMin=2016-12-08T17%3A45%3A47.379417Z&orderBy=startTime
INFO:googleapiclient.discovery:URL being requested: GET https://www.googleapis.com/calendar/v3/calendars/4dg6pu1jnusdpnkump4frglocs%40group.calendar.google.com/events?singleEvents=true&alt=json&maxResults=5&timeMin=2016-12-08T17%3A45%3A47.379417Z&orderBy=startTime
INFO:googleapiclient.discovery:URL being requested: GET https://www.googleapis.com/calendar/v3/calendars/8jaema1ucgrt3g03fjuv8r5smk%40group.calendar.google.com/events?singleEvents=true&alt=json&maxResults=5&timeMin=2016-12-08T17%3A45%3A47.379417Z&orderBy=startTime
INFO:googleapiclient.discovery:URL being requested: GET https://www.googleapis.com/calendar/v3/calendars/euokutpi37i11v0h3igns7fjh4%40group.calendar.google.com/events?singleEvents=true&alt=json&maxResults=5&timeMin=2016-12-08T17%3A45%3A47.379417Z&orderBy=startTime
WARNING:googleapiclient.discovery_cache:file_cache is unavailable when using oauth2client >= 4.0.0
Traceback (most recent call last):
  File "C:\Program Files (x86)\Python\Python-3.5.2\lib\site-packages\googleapiclient\discovery_cache\__init__.py", line 36, in autodetect
    from google.appengine.api import memcache
ImportError: No module named 'google'

During handling of the above exception, another exception occurred:

Traceback (most recent call last):
  File "C:\Program Files (x86)\Python\Python-3.5.2\lib\site-packages\googleapiclient\discovery_cache\file_cache.py", line 33, in <module>
    from oauth2client.contrib.locked_file import LockedFile
ImportError: No module named 'oauth2client.contrib.locked_file'

During handling of the above exception, another exception occurred:

Traceback (most recent call last):
  File "C:\Program Files (x86)\Python\Python-3.5.2\lib\site-packages\googleapiclient\discovery_cache\file_cache.py", line 37, in <module>
    from oauth2client.locked_file import LockedFile
ImportError: No module named 'oauth2client.locked_file'

During handling of the above exception, another exception occurred:

Traceback (most recent call last):
  File "C:\Program Files (x86)\Python\Python-3.5.2\lib\site-packages\googleapiclient\discovery_cache\__init__.py", line 41, in autodetect
    from . import file_cache
  File "C:\Program Files (x86)\Python\Python-3.5.2\lib\site-packages\googleapiclient\discovery_cache\file_cache.py", line 41, in <module>
    'file_cache is unavailable when using oauth2client >= 4.0.0')
ImportError: file_cache is unavailable when using oauth2client >= 4.0.0
INFO:googleapiclient.discovery:URL being requested: GET https://www.googleapis.com/discovery/v1/apis/calendar/v3/rest
INFO:googleapiclient.discovery:URL being requested: GET https://www.googleapis.com/calendar/v3/calendars/g0tostl4q2q8dc3kblkqtuuv6g%40group.calendar.google.com/events?singleEvents=true&alt=json&maxResults=5&timeMin=2016-12-08T17%3A46%3A06.483752Z&orderBy=startTime
INFO:googleapiclient.discovery:URL being requested: GET https://www.googleapis.com/calendar/v3/calendars/4dg6pu1jnusdpnkump4frglocs%40group.calendar.google.com/events?singleEvents=true&alt=json&maxResults=5&timeMin=2016-12-08T17%3A46%3A06.483752Z&orderBy=startTime
INFO:googleapiclient.discovery:URL being requested: GET https://www.googleapis.com/calendar/v3/calendars/8jaema1ucgrt3g03fjuv8r5smk%40group.calendar.google.com/events?singleEvents=true&alt=json&maxResults=5&timeMin=2016-12-08T17%3A46%3A06.483752Z&orderBy=startTime
INFO:googleapiclient.discovery:URL being requested: GET https://www.googleapis.com/calendar/v3/calendars/euokutpi37i11v0h3igns7fjh4%40group.calendar.google.com/events?singleEvents=true&alt=json&maxResults=5&timeMin=2016-12-08T17%3A46%3A06.483752Z&orderBy=startTime
WARNING:googleapiclient.discovery_cache:file_cache is unavailable when using oauth2client >= 4.0.0
Traceback (most recent call last):
  File "C:\Program Files (x86)\Python\Python-3.5.2\lib\site-packages\googleapiclient\discovery_cache\__init__.py", line 36, in autodetect
    from google.appengine.api import memcache
ImportError: No module named 'google'

During handling of the above exception, another exception occurred:

Traceback (most recent call last):
  File "C:\Program Files (x86)\Python\Python-3.5.2\lib\site-packages\googleapiclient\discovery_cache\file_cache.py", line 33, in <module>
    from oauth2client.contrib.locked_file import LockedFile
ImportError: No module named 'oauth2client.contrib.locked_file'

During handling of the above exception, another exception occurred:

Traceback (most recent call last):
  File "C:\Program Files (x86)\Python\Python-3.5.2\lib\site-packages\googleapiclient\discovery_cache\file_cache.py", line 37, in <module>
    from oauth2client.locked_file import LockedFile
ImportError: No module named 'oauth2client.locked_file'

During handling of the above exception, another exception occurred:

Traceback (most recent call last):
  File "C:\Program Files (x86)\Python\Python-3.5.2\lib\site-packages\googleapiclient\discovery_cache\__init__.py", line 41, in autodetect
    from . import file_cache
  File "C:\Program Files (x86)\Python\Python-3.5.2\lib\site-packages\googleapiclient\discovery_cache\file_cache.py", line 41, in <module>
    'file_cache is unavailable when using oauth2client >= 4.0.0')
ImportError: file_cache is unavailable when using oauth2client >= 4.0.0
INFO:googleapiclient.discovery:URL being requested: GET https://www.googleapis.com/discovery/v1/apis/calendar/v3/rest
INFO:googleapiclient.discovery:URL being requested: GET https://www.googleapis.com/calendar/v3/calendars/g0tostl4q2q8dc3kblkqtuuv6g%40group.calendar.google.com/events?singleEvents=true&alt=json&maxResults=5&timeMin=2016-12-08T17%3A46%3A07.422751Z&orderBy=startTime
INFO:googleapiclient.discovery:URL being requested: GET https://www.googleapis.com/calendar/v3/calendars/4dg6pu1jnusdpnkump4frglocs%40group.calendar.google.com/events?singleEvents=true&alt=json&maxResults=5&timeMin=2016-12-08T17%3A46%3A07.422751Z&orderBy=startTime
INFO:googleapiclient.discovery:URL being requested: GET https://www.googleapis.com/calendar/v3/calendars/8jaema1ucgrt3g03fjuv8r5smk%40group.calendar.google.com/events?singleEvents=true&alt=json&maxResults=5&timeMin=2016-12-08T17%3A46%3A07.422751Z&orderBy=startTime
INFO:googleapiclient.discovery:URL being requested: GET https://www.googleapis.com/calendar/v3/calendars/euokutpi37i11v0h3igns7fjh4%40group.calendar.google.com/events?singleEvents=true&alt=json&maxResults=5&timeMin=2016-12-08T17%3A46%3A07.422751Z&orderBy=startTime
WARNING:googleapiclient.discovery_cache:file_cache is unavailable when using oauth2client >= 4.0.0
Traceback (most recent call last):
  File "C:\Program Files (x86)\Python\Python-3.5.2\lib\site-packages\googleapiclient\discovery_cache\__init__.py", line 36, in autodetect
    from google.appengine.api import memcache
ImportError: No module named 'google'

During handling of the above exception, another exception occurred:

Traceback (most recent call last):
  File "C:\Program Files (x86)\Python\Python-3.5.2\lib\site-packages\googleapiclient\discovery_cache\file_cache.py", line 33, in <module>
    from oauth2client.contrib.locked_file import LockedFile
ImportError: No module named 'oauth2client.contrib.locked_file'

During handling of the above exception, another exception occurred:

Traceback (most recent call last):
  File "C:\Program Files (x86)\Python\Python-3.5.2\lib\site-packages\googleapiclient\discovery_cache\file_cache.py", line 37, in <module>
    from oauth2client.locked_file import LockedFile
ImportError: No module named 'oauth2client.locked_file'

During handling of the above exception, another exception occurred:

Traceback (most recent call last):
  File "C:\Program Files (x86)\Python\Python-3.5.2\lib\site-packages\googleapiclient\discovery_cache\__init__.py", line 41, in autodetect
    from . import file_cache
  File "C:\Program Files (x86)\Python\Python-3.5.2\lib\site-packages\googleapiclient\discovery_cache\file_cache.py", line 41, in <module>
    'file_cache is unavailable when using oauth2client >= 4.0.0')
ImportError: file_cache is unavailable when using oauth2client >= 4.0.0
INFO:googleapiclient.discovery:URL being requested: GET https://www.googleapis.com/discovery/v1/apis/calendar/v3/rest
INFO:googleapiclient.discovery:URL being requested: GET https://www.googleapis.com/calendar/v3/calendars/g0tostl4q2q8dc3kblkqtuuv6g%40group.calendar.google.com/events?singleEvents=true&alt=json&maxResults=5&timeMin=2016-12-08T17%3A46%3A08.459507Z&orderBy=startTime
INFO:googleapiclient.discovery:URL being requested: GET https://www.googleapis.com/calendar/v3/calendars/4dg6pu1jnusdpnkump4frglocs%40group.calendar.google.com/events?singleEvents=true&alt=json&maxResults=5&timeMin=2016-12-08T17%3A46%3A08.459507Z&orderBy=startTime
INFO:googleapiclient.discovery:URL being requested: GET https://www.googleapis.com/calendar/v3/calendars/8jaema1ucgrt3g03fjuv8r5smk%40group.calendar.google.com/events?singleEvents=true&alt=json&maxResults=5&timeMin=2016-12-08T17%3A46%3A08.459507Z&orderBy=startTime
INFO:googleapiclient.discovery:URL being requested: GET https://www.googleapis.com/calendar/v3/calendars/euokutpi37i11v0h3igns7fjh4%40group.calendar.google.com/events?singleEvents=true&alt=json&maxResults=5&timeMin=2016-12-08T17%3A46%3A08.459507Z&orderBy=startTime
WARNING:googleapiclient.discovery_cache:file_cache is unavailable when using oauth2client >= 4.0.0
Traceback (most recent call last):
  File "C:\Program Files (x86)\Python\Python-3.5.2\lib\site-packages\googleapiclient\discovery_cache\__init__.py", line 36, in autodetect
    from google.appengine.api import memcache
ImportError: No module named 'google'

During handling of the above exception, another exception occurred:

Traceback (most recent call last):
  File "C:\Program Files (x86)\Python\Python-3.5.2\lib\site-packages\googleapiclient\discovery_cache\file_cache.py", line 33, in <module>
    from oauth2client.contrib.locked_file import LockedFile
ImportError: No module named 'oauth2client.contrib.locked_file'

During handling of the above exception, another exception occurred:

Traceback (most recent call last):
  File "C:\Program Files (x86)\Python\Python-3.5.2\lib\site-packages\googleapiclient\discovery_cache\file_cache.py", line 37, in <module>
    from oauth2client.locked_file import LockedFile
ImportError: No module named 'oauth2client.locked_file'

During handling of the above exception, another exception occurred:

Traceback (most recent call last):
  File "C:\Program Files (x86)\Python\Python-3.5.2\lib\site-packages\googleapiclient\discovery_cache\__init__.py", line 41, in autodetect
    from . import file_cache
  File "C:\Program Files (x86)\Python\Python-3.5.2\lib\site-packages\googleapiclient\discovery_cache\file_cache.py", line 41, in <module>
    'file_cache is unavailable when using oauth2client >= 4.0.0')
ImportError: file_cache is unavailable when using oauth2client >= 4.0.0
INFO:googleapiclient.discovery:URL being requested: GET https://www.googleapis.com/discovery/v1/apis/calendar/v3/rest
INFO:googleapiclient.discovery:URL being requested: GET https://www.googleapis.com/calendar/v3/calendars/g0tostl4q2q8dc3kblkqtuuv6g%40group.calendar.google.com/events?singleEvents=true&alt=json&maxResults=5&timeMin=2016-12-08T17%3A46%3A43.575902Z&orderBy=startTime
INFO:googleapiclient.discovery:URL being requested: GET https://www.googleapis.com/calendar/v3/calendars/4dg6pu1jnusdpnkump4frglocs%40group.calendar.google.com/events?singleEvents=true&alt=json&maxResults=5&timeMin=2016-12-08T17%3A46%3A43.575902Z&orderBy=startTime
INFO:googleapiclient.discovery:URL being requested: GET https://www.googleapis.com/calendar/v3/calendars/8jaema1ucgrt3g03fjuv8r5smk%40group.calendar.google.com/events?singleEvents=true&alt=json&maxResults=5&timeMin=2016-12-08T17%3A46%3A43.575902Z&orderBy=startTime
INFO:googleapiclient.discovery:URL being requested: GET https://www.googleapis.com/calendar/v3/calendars/euokutpi37i11v0h3igns7fjh4%40group.calendar.google.com/events?singleEvents=true&alt=json&maxResults=5&timeMin=2016-12-08T17%3A46%3A43.575902Z&orderBy=startTime
WARNING:googleapiclient.discovery_cache:file_cache is unavailable when using oauth2client >= 4.0.0
Traceback (most recent call last):
  File "C:\Program Files (x86)\Python\Python-3.5.2\lib\site-packages\googleapiclient\discovery_cache\__init__.py", line 36, in autodetect
    from google.appengine.api import memcache
ImportError: No module named 'google'

During handling of the above exception, another exception occurred:

Traceback (most recent call last):
  File "C:\Program Files (x86)\Python\Python-3.5.2\lib\site-packages\googleapiclient\discovery_cache\file_cache.py", line 33, in <module>
    from oauth2client.contrib.locked_file import LockedFile
ImportError: No module named 'oauth2client.contrib.locked_file'

During handling of the above exception, another exception occurred:

Traceback (most recent call last):
  File "C:\Program Files (x86)\Python\Python-3.5.2\lib\site-packages\googleapiclient\discovery_cache\file_cache.py", line 37, in <module>
    from oauth2client.locked_file import LockedFile
ImportError: No module named 'oauth2client.locked_file'

During handling of the above exception, another exception occurred:

Traceback (most recent call last):
  File "C:\Program Files (x86)\Python\Python-3.5.2\lib\site-packages\googleapiclient\discovery_cache\__init__.py", line 41, in autodetect
    from . import file_cache
  File "C:\Program Files (x86)\Python\Python-3.5.2\lib\site-packages\googleapiclient\discovery_cache\file_cache.py", line 41, in <module>
    'file_cache is unavailable when using oauth2client >= 4.0.0')
ImportError: file_cache is unavailable when using oauth2client >= 4.0.0
INFO:googleapiclient.discovery:URL being requested: GET https://www.googleapis.com/discovery/v1/apis/calendar/v3/rest
INFO:googleapiclient.discovery:URL being requested: GET https://www.googleapis.com/calendar/v3/calendars/g0tostl4q2q8dc3kblkqtuuv6g%40group.calendar.google.com/events?maxResults=5&orderBy=startTime&timeMin=2016-12-10T19%3A55%3A01.804014Z&singleEvents=true&alt=json
INFO:googleapiclient.discovery:URL being requested: GET https://www.googleapis.com/calendar/v3/calendars/4dg6pu1jnusdpnkump4frglocs%40group.calendar.google.com/events?maxResults=5&orderBy=startTime&timeMin=2016-12-10T19%3A55%3A01.804014Z&singleEvents=true&alt=json
INFO:googleapiclient.discovery:URL being requested: GET https://www.googleapis.com/calendar/v3/calendars/8jaema1ucgrt3g03fjuv8r5smk%40group.calendar.google.com/events?maxResults=5&orderBy=startTime&timeMin=2016-12-10T19%3A55%3A01.804014Z&singleEvents=true&alt=json
INFO:googleapiclient.discovery:URL being requested: GET https://www.googleapis.com/calendar/v3/calendars/euokutpi37i11v0h3igns7fjh4%40group.calendar.google.com/events?maxResults=5&orderBy=startTime&timeMin=2016-12-10T19%3A55%3A01.804014Z&singleEvents=true&alt=json
